[INFO] [2021-06-15 21:22:04,144] [7:140196188256000] - dag_scheduler.py[line:40]: submit job, job_id 2021061521220414378611, body {'job_dsl': {}, 'job_runtime_conf': {'dsl_version': 2, 'initiator': {'role': 'guest', 'party_id': 9999}, 'role': {'host': [9998], 'guest': [9999]}, 'job_parameters': {'common': {'work_mode': 0, 'backend': 0, 'job_type': 'predict', 'model_id': 'guest-9999#host-9998#model', 'model_version': '202106152108460902496'}}, 'component_parameters': {'role': {'guest': {'0': {'reader_0': {'table': {'name': 'default_credit_hetero_guest', 'namespace': 'experiment'}}}}, 'host': {'0': {'reader_0': {'table': {'name': 'default_credit_hetero_host', 'namespace': 'experiment'}}}}}}, 'conf_path': './examples/LDPDev/test_predict_conf.json'}}
[INFO] [2021-06-15 21:22:04,233] [7:140198455301888] - job_controller.py[line:52]: job parameters:{'backend': 0, 'spark_run': {}, 'adaptation_parameters': {'task_memory_per_node': 0, 'if_initiator_baseline': True, 'task_cores_per_node': 4, 'request_task_cores': 4, 'task_nodes': 1}, 'federation_engine': 'STANDALONE', 'computing_engine': 'STANDALONE', 'storage_engine': 'STANDALONE', 'task_parallelism': 1, 'federated_status_collect_type': 'PULL', 'pulsar_run': {}, 'engines_address': {}, 'federated_mode': 'SINGLE', 'computing_partitions': 4, 'work_mode': 0, 'job_type': 'predict', 'eggroll_run': {}, 'model_version': '202106152108460902496', 'model_id': 'guest-9999#host-9998#model', 'rabbitmq_run': {}}
[INFO] [2021-06-15 21:22:04,348] [7:140198455301888] - job_controller.py[line:52]: job parameters:{'backend': 0, 'spark_run': {}, 'adaptation_parameters': {'task_memory_per_node': 0, 'if_initiator_baseline': True, 'task_cores_per_node': 4, 'request_task_cores': 4, 'task_nodes': 1}, 'federation_engine': 'STANDALONE', 'computing_engine': 'STANDALONE', 'storage_engine': 'STANDALONE', 'task_parallelism': 1, 'federated_status_collect_type': 'PULL', 'pulsar_run': {}, 'engines_address': {}, 'federated_mode': 'SINGLE', 'computing_partitions': 4, 'work_mode': 0, 'job_type': 'predict', 'eggroll_run': {}, 'model_version': '202106152108460902496', 'model_id': 'guest-9999#host-9998#model', 'rabbitmq_run': {}}
[INFO] [2021-06-15 21:22:04,448] [7:140196188256000] - dag_scheduler.py[line:122]: submit job successfully, job id is 2021061521220414378611, model id is guest-9999#host-9998#model
[INFO] [2021-06-15 21:22:05,487] [7:140197562341120] - federated_scheduler.py[line:39]: try to apply job 2021061521220414378611 resource
[INFO] [2021-06-15 21:22:05,514] [7:140196188256000] - resource_manager.py[line:176]: apply job 2021061521220414378611 resource(cores 4 memory 0) on host 9998 successfully, remaining cores: 16 remaining memory: 0
[INFO] [2021-06-15 21:22:05,546] [7:140196188256000] - resource_manager.py[line:176]: apply job 2021061521220414378611 resource(cores 4 memory 0) on guest 9999 successfully, remaining cores: 12 remaining memory: 0
[INFO] [2021-06-15 21:22:05,550] [7:140197562341120] - federated_scheduler.py[line:42]: apply job 2021061521220414378611 resource successfully
[INFO] [2021-06-15 21:22:05,550] [7:140197562341120] - dag_scheduler.py[line:279]: try to start job 2021061521220414378611 on initiator guest 9999
[INFO] [2021-06-15 21:22:05,565] [7:140196188256000] - job_controller.py[line:261]: try to start job 2021061521220414378611 on host 9998
[INFO] [2021-06-15 21:22:05,565] [7:140196188256000] - job_saver.py[line:45]: try to update job 2021061521220414378611 status to running
[INFO] [2021-06-15 21:22:05,585] [7:140196188256000] - job_saver.py[line:48]: update job 2021061521220414378611 status successfully
[INFO] [2021-06-15 21:22:05,585] [7:140196188256000] - job_saver.py[line:61]: try to update job 2021061521220414378611
[INFO] [2021-06-15 21:22:05,604] [7:140196188256000] - job_saver.py[line:64]: job 2021061521220414378611 update successfully: {'job_id': '2021061521220414378611', 'role': 'host', 'party_id': 9998, 'status': 'running', 'start_time': 1623792125565}
[INFO] [2021-06-15 21:22:05,605] [7:140196188256000] - job_controller.py[line:275]: start job 2021061521220414378611 on host 9998 successfully
[INFO] [2021-06-15 21:22:05,615] [7:140196188256000] - job_controller.py[line:261]: try to start job 2021061521220414378611 on guest 9999
[INFO] [2021-06-15 21:22:05,616] [7:140196188256000] - job_saver.py[line:45]: try to update job 2021061521220414378611 status to running
[INFO] [2021-06-15 21:22:05,636] [7:140196188256000] - job_saver.py[line:48]: update job 2021061521220414378611 status successfully
[INFO] [2021-06-15 21:22:05,636] [7:140196188256000] - job_saver.py[line:61]: try to update job 2021061521220414378611
[INFO] [2021-06-15 21:22:05,656] [7:140196188256000] - job_saver.py[line:64]: job 2021061521220414378611 update successfully: {'job_id': '2021061521220414378611', 'role': 'guest', 'party_id': 9999, 'status': 'running', 'start_time': 1623792125615}
[INFO] [2021-06-15 21:22:05,656] [7:140196188256000] - job_controller.py[line:275]: start job 2021061521220414378611 on guest 9999 successfully
[INFO] [2021-06-15 21:22:05,662] [7:140197562341120] - dag_scheduler.py[line:292]: start job 2021061521220414378611 on initiator guest 9999
[INFO] [2021-06-15 21:22:05,674] [7:140197562341120] - dag_scheduler.py[line:247]: reset job 2021061521220414378611 ready signal True
[INFO] [2021-06-15 21:22:05,685] [7:140197562341120] - dag_scheduler.py[line:298]: scheduling job 2021061521220414378611
[INFO] [2021-06-15 21:22:05,705] [7:140197562341120] - task_scheduler.py[line:28]: scheduling job 2021061521220414378611 tasks
[INFO] [2021-06-15 21:22:05,730] [7:140197562341120] - task_scheduler.py[line:143]: job 2021061521220414378611 task 2021061521220414378611_dataio_0 0 status is waiting, calculate by task party status list: ['waiting', 'waiting']
[INFO] [2021-06-15 21:22:05,745] [7:140197562341120] - task_scheduler.py[line:143]: job 2021061521220414378611 task 2021061521220414378611_intersection_0 0 status is waiting, calculate by task party status list: ['waiting', 'waiting']
[INFO] [2021-06-15 21:22:05,759] [7:140197562341120] - task_scheduler.py[line:143]: job 2021061521220414378611 task 2021061521220414378611_hetero_secure_boost_0 0 status is waiting, calculate by task party status list: ['waiting', 'waiting']
[INFO] [2021-06-15 21:22:05,760] [7:140197562341120] - task_scheduler.py[line:80]: try to start job 2021061521220414378611 task 2021061521220414378611_dataio_0 0 on guest 9999
[INFO] [2021-06-15 21:22:05,777] [7:140197562341120] - resource_manager.py[line:286]: task 2021061521220414378611_dataio_0 0 apply resource successfully
[INFO] [2021-06-15 21:22:05,777] [7:140197562341120] - job_saver.py[line:71]: try to update job 2021061521220414378611 task 2021061521220414378611_dataio_0 0 status
[INFO] [2021-06-15 21:22:05,795] [7:140197562341120] - job_saver.py[line:74]: update job 2021061521220414378611 task 2021061521220414378611_dataio_0 0 status successfully: {'job_id': '2021061521220414378611', 'task_id': '2021061521220414378611_dataio_0', 'task_version': 0, 'role': 'guest', 'party_id': '9999', 'status': 'running'}
[INFO] [2021-06-15 21:22:05,795] [7:140197562341120] - task_scheduler.py[line:93]: start job 2021061521220414378611 task 2021061521220414378611_dataio_0 0 on guest 9999
[INFO] [2021-06-15 21:22:05,795] [7:140197562341120] - federated_scheduler.py[line:192]: job 2021061521220414378611 task 2021061521220414378611_dataio_0 0 is running, sync to all party
[INFO] [2021-06-15 21:22:05,817] [7:140196188256000] - job_saver.py[line:71]: try to update job 2021061521220414378611 task 2021061521220414378611_dataio_0 0 status
[INFO] [2021-06-15 21:22:05,826] [7:140196188256000] - job_saver.py[line:76]: update job 2021061521220414378611 task 2021061521220414378611_dataio_0 0 status update does not take effect: {'job_id': '2021061521220414378611', 'task_id': '2021061521220414378611_dataio_0', 'task_version': '0', 'role': 'guest', 'party_id': '9999', 'status': 'running'}
[WARNING] [2021-06-15 21:22:05,838] [7:140197562341120] - federated_scheduler.py[line:260]: an error occurred while status/running the task to role guest party 9999: 
update task status failed
[INFO] [2021-06-15 21:22:05,845] [7:140196188256000] - job_saver.py[line:71]: try to update job 2021061521220414378611 task 2021061521220414378611_dataio_0 0 status
[INFO] [2021-06-15 21:22:05,862] [7:140196188256000] - job_saver.py[line:74]: update job 2021061521220414378611 task 2021061521220414378611_dataio_0 0 status successfully: {'job_id': '2021061521220414378611', 'task_id': '2021061521220414378611_dataio_0', 'task_version': '0', 'role': 'host', 'party_id': '9998', 'status': 'running'}
[INFO] [2021-06-15 21:22:05,873] [7:140197562341120] - federated_scheduler.py[line:197]: sync job 2021061521220414378611 task 2021061521220414378611_dataio_0 0 status running to all party failed: 
{'guest': {9999: {'retcode': 103, 'retmsg': 'update task status failed'}}, 'host': {9998: {'retcode': 0, 'retmsg': 'success'}}}
[INFO] [2021-06-15 21:22:05,897] [7:140196188256000] - task_controller.py[line:71]: try to start job 2021061521220414378611 task 2021061521220414378611_dataio_0 0 on guest 9999 executor subprocess
[INFO] [2021-06-15 21:22:05,902] [7:140196188256000] - task_controller.py[line:90]: use computing engine STANDALONE
[INFO] [2021-06-15 21:22:05,902] [7:140196188256000] - task_controller.py[line:145]: job 2021061521220414378611 task 2021061521220414378611_dataio_0 0 on guest 9999 executor subprocess is ready
[INFO] [2021-06-15 21:22:05,902] [7:140196188256000] - job_utils.py[line:310]: start process command: /usr/local/bin/python /fate/python/fate_flow/operation/task_executor.py -j 2021061521220414378611 -n dataio_0 -t 2021061521220414378611_dataio_0 -v 0 -r guest -p 9999 -c /fate/jobs/2021061521220414378611/guest/9999/dataio_0/2021061521220414378611_dataio_0/0/task_parameters.json --run_ip 127.0.0.1 --job_server 127.0.0.1:9380
[INFO] [2021-06-15 21:22:05,911] [7:140196188256000] - job_utils.py[line:334]: start process command: /usr/local/bin/python /fate/python/fate_flow/operation/task_executor.py -j 2021061521220414378611 -n dataio_0 -t 2021061521220414378611_dataio_0 -v 0 -r guest -p 9999 -c /fate/jobs/2021061521220414378611/guest/9999/dataio_0/2021061521220414378611_dataio_0/0/task_parameters.json --run_ip 127.0.0.1 --job_server 127.0.0.1:9380 successfully, pid is 2075
[INFO] [2021-06-15 21:22:05,912] [7:140196188256000] - job_saver.py[line:81]: try to update job 2021061521220414378611 task 2021061521220414378611_dataio_0 0
[INFO] [2021-06-15 21:22:05,937] [7:140196188256000] - job_saver.py[line:84]: job 2021061521220414378611 task 2021061521220414378611_dataio_0 0 update successfully
[INFO] [2021-06-15 21:22:05,944] [7:140196188256000] - job_saver.py[line:71]: try to update job 2021061521220414378611 task 2021061521220414378611_dataio_0 0 status
[INFO] [2021-06-15 21:22:05,962] [7:140196188256000] - job_saver.py[line:74]: update job 2021061521220414378611 task 2021061521220414378611_dataio_0 0 status successfully: {'job_id': '2021061521220414378611', 'task_id': '2021061521220414378611_dataio_0', 'task_version': '0', 'role': 'guest', 'party_id': '9999', 'party_status': 'running', 'start_time': 1623792125911}
[INFO] [2021-06-15 21:22:05,970] [7:140196188256000] - task_controller.py[line:164]: job 2021061521220414378611 task 2021061521220414378611_dataio_0 0 on guest 9999 executor subprocess start success
[INFO] [2021-06-15 21:22:05,987] [7:140196188256000] - task_controller.py[line:71]: try to start job 2021061521220414378611 task 2021061521220414378611_dataio_0 0 on host 9998 executor subprocess
[INFO] [2021-06-15 21:22:05,992] [7:140196188256000] - task_controller.py[line:90]: use computing engine STANDALONE
[INFO] [2021-06-15 21:22:05,993] [7:140196188256000] - task_controller.py[line:145]: job 2021061521220414378611 task 2021061521220414378611_dataio_0 0 on host 9998 executor subprocess is ready
[INFO] [2021-06-15 21:22:05,993] [7:140196188256000] - job_utils.py[line:310]: start process command: /usr/local/bin/python /fate/python/fate_flow/operation/task_executor.py -j 2021061521220414378611 -n dataio_0 -t 2021061521220414378611_dataio_0 -v 0 -r host -p 9998 -c /fate/jobs/2021061521220414378611/host/9998/dataio_0/2021061521220414378611_dataio_0/0/task_parameters.json --run_ip 127.0.0.1 --job_server 127.0.0.1:9380
[INFO] [2021-06-15 21:22:06,001] [7:140196188256000] - job_utils.py[line:334]: start process command: /usr/local/bin/python /fate/python/fate_flow/operation/task_executor.py -j 2021061521220414378611 -n dataio_0 -t 2021061521220414378611_dataio_0 -v 0 -r host -p 9998 -c /fate/jobs/2021061521220414378611/host/9998/dataio_0/2021061521220414378611_dataio_0/0/task_parameters.json --run_ip 127.0.0.1 --job_server 127.0.0.1:9380 successfully, pid is 2077
[INFO] [2021-06-15 21:22:06,001] [7:140196188256000] - job_saver.py[line:81]: try to update job 2021061521220414378611 task 2021061521220414378611_dataio_0 0
[INFO] [2021-06-15 21:22:06,020] [7:140196188256000] - job_saver.py[line:84]: job 2021061521220414378611 task 2021061521220414378611_dataio_0 0 update successfully
[INFO] [2021-06-15 21:22:06,028] [7:140196188256000] - job_saver.py[line:71]: try to update job 2021061521220414378611 task 2021061521220414378611_dataio_0 0 status
[INFO] [2021-06-15 21:22:06,047] [7:140196188256000] - job_saver.py[line:74]: update job 2021061521220414378611 task 2021061521220414378611_dataio_0 0 status successfully: {'job_id': '2021061521220414378611', 'task_id': '2021061521220414378611_dataio_0', 'task_version': '0', 'role': 'host', 'party_id': '9998', 'party_status': 'running', 'start_time': 1623792126001}
[INFO] [2021-06-15 21:22:06,054] [7:140196188256000] - task_controller.py[line:164]: job 2021061521220414378611 task 2021061521220414378611_dataio_0 0 on host 9998 executor subprocess start success
[INFO] [2021-06-15 21:22:06,060] [7:140197562341120] - task_scheduler.py[line:75]: finish scheduling job 2021061521220414378611 tasks
[INFO] [2021-06-15 21:22:06,061] [7:140197562341120] - dag_scheduler.py[line:310]: Job 2021061521220414378611 status is running, calculate by task status list: ['running', 'waiting', 'waiting']
[INFO] [2021-06-15 21:22:06,061] [7:140197562341120] - dag_scheduler.py[line:325]: finish scheduling job 2021061521220414378611
[INFO] [2021-06-15 21:22:07,697] [2075:140167217764160] - task_executor.py[line:56]: enter task process
[INFO] [2021-06-15 21:22:07,698] [2075:140167217764160] - task_executor.py[line:57]: Namespace(component_name='dataio_0', config='/fate/jobs/2021061521220414378611/guest/9999/dataio_0/2021061521220414378611_dataio_0/0/task_parameters.json', job_id='2021061521220414378611', job_server='127.0.0.1:9380', party_id=9999, role='guest', run_ip='127.0.0.1', task_id='2021061521220414378611_dataio_0', task_version=0)
[INFO] [2021-06-15 21:22:07,706] [2077:140419511437120] - task_executor.py[line:56]: enter task process
[INFO] [2021-06-15 21:22:07,706] [2077:140419511437120] - task_executor.py[line:57]: Namespace(component_name='dataio_0', config='/fate/jobs/2021061521220414378611/host/9998/dataio_0/2021061521220414378611_dataio_0/0/task_parameters.json', job_id='2021061521220414378611', job_server='127.0.0.1:9380', party_id=9998, role='host', run_ip='127.0.0.1', task_id='2021061521220414378611_dataio_0', task_version=0)
[INFO] [2021-06-15 21:22:07,832] [7:140196188256000] - job_saver.py[line:81]: try to update job 2021061521220414378611 task 2021061521220414378611_dataio_0 0
[INFO] [2021-06-15 21:22:07,847] [7:140196188256000] - job_saver.py[line:84]: job 2021061521220414378611 task 2021061521220414378611_dataio_0 0 update successfully
[INFO] [2021-06-15 21:22:07,852] [7:140196188256000] - job_saver.py[line:71]: try to update job 2021061521220414378611 task 2021061521220414378611_dataio_0 0 status
[INFO] [2021-06-15 21:22:07,857] [7:140196188256000] - job_saver.py[line:76]: update job 2021061521220414378611 task 2021061521220414378611_dataio_0 0 status update does not take effect: {'job_id': '2021061521220414378611', 'component_name': 'dataio_0', 'task_id': '2021061521220414378611_dataio_0', 'task_version': '0', 'role': 'guest', 'party_id': '9999', 'run_ip': '127.0.0.1', 'run_pid': 2075, 'party_status': 'running'}
[INFO] [2021-06-15 21:22:07,890] [7:140196188256000] - job_saver.py[line:81]: try to update job 2021061521220414378611 task 2021061521220414378611_dataio_0 0
[INFO] [2021-06-15 21:22:07,909] [7:140196188256000] - job_saver.py[line:84]: job 2021061521220414378611 task 2021061521220414378611_dataio_0 0 update successfully
[INFO] [2021-06-15 21:22:07,915] [7:140196188256000] - job_saver.py[line:71]: try to update job 2021061521220414378611 task 2021061521220414378611_dataio_0 0 status
[INFO] [2021-06-15 21:22:07,919] [7:140196188256000] - job_saver.py[line:76]: update job 2021061521220414378611 task 2021061521220414378611_dataio_0 0 status update does not take effect: {'job_id': '2021061521220414378611', 'component_name': 'dataio_0', 'task_id': '2021061521220414378611_dataio_0', 'task_version': '0', 'role': 'host', 'party_id': '9998', 'run_ip': '127.0.0.1', 'run_pid': 2077, 'party_status': 'running'}
[INFO] [2021-06-15 21:22:08,113] [7:140197562341120] - dag_scheduler.py[line:298]: scheduling job 2021061521220414378611
[INFO] [2021-06-15 21:22:08,132] [7:140197562341120] - task_scheduler.py[line:28]: scheduling job 2021061521220414378611 tasks
[INFO] [2021-06-15 21:22:08,176] [7:140197562341120] - job_saver.py[line:71]: try to update job 2021061521220414378611 task 2021061521220414378611_dataio_0 0 status
[INFO] [2021-06-15 21:22:08,181] [7:140197562341120] - job_saver.py[line:76]: update job 2021061521220414378611 task 2021061521220414378611_dataio_0 0 status update does not take effect: {'elapsed': None, 'end_time': None, 'job_id': '2021061521220414378611', 'party_id': '9999', 'party_status': 'running', 'role': 'guest', 'start_time': 1623792125911, 'status': 'running', 'task_id': '2021061521220414378611_dataio_0', 'task_version': 0, 'update_time': 1623792124372}
[INFO] [2021-06-15 21:22:08,181] [7:140197562341120] - job_saver.py[line:81]: try to update job 2021061521220414378611 task 2021061521220414378611_dataio_0 0
[INFO] [2021-06-15 21:22:08,199] [7:140197562341120] - job_saver.py[line:84]: job 2021061521220414378611 task 2021061521220414378611_dataio_0 0 update successfully
[INFO] [2021-06-15 21:22:08,199] [7:140197562341120] - job_saver.py[line:71]: try to update job 2021061521220414378611 task 2021061521220414378611_dataio_0 0 status
[INFO] [2021-06-15 21:22:08,204] [7:140197562341120] - job_saver.py[line:76]: update job 2021061521220414378611 task 2021061521220414378611_dataio_0 0 status update does not take effect: {'elapsed': None, 'end_time': None, 'job_id': '2021061521220414378611', 'party_id': '9998', 'party_status': 'running', 'role': 'host', 'start_time': 1623792126001, 'status': 'running', 'task_id': '2021061521220414378611_dataio_0', 'task_version': 0, 'update_time': 1623792124256}
[INFO] [2021-06-15 21:22:08,204] [7:140197562341120] - job_saver.py[line:81]: try to update job 2021061521220414378611 task 2021061521220414378611_dataio_0 0
[INFO] [2021-06-15 21:22:08,213] [7:140196188256000] - job_saver.py[line:81]: try to update job 2021061521220414378611 task 2021061521220414378611_dataio_0 0
[INFO] [2021-06-15 21:22:08,219] [7:140197562341120] - job_saver.py[line:84]: job 2021061521220414378611 task 2021061521220414378611_dataio_0 0 update successfully
[INFO] [2021-06-15 21:22:08,225] [7:140197562341120] - task_scheduler.py[line:143]: job 2021061521220414378611 task 2021061521220414378611_dataio_0 0 status is running, calculate by task party status list: ['running', 'running']
[INFO] [2021-06-15 21:22:08,238] [7:140196188256000] - job_saver.py[line:84]: job 2021061521220414378611 task 2021061521220414378611_dataio_0 0 update successfully
[INFO] [2021-06-15 21:22:08,243] [7:140196188256000] - job_saver.py[line:71]: try to update job 2021061521220414378611 task 2021061521220414378611_dataio_0 0 status
[INFO] [2021-06-15 21:22:08,246] [7:140197562341120] - task_scheduler.py[line:143]: job 2021061521220414378611 task 2021061521220414378611_intersection_0 0 status is waiting, calculate by task party status list: ['waiting', 'waiting']
[INFO] [2021-06-15 21:22:08,253] [7:140198455301888] - job_saver.py[line:81]: try to update job 2021061521220414378611 task 2021061521220414378611_dataio_0 0
[INFO] [2021-06-15 21:22:08,262] [7:140196188256000] - job_saver.py[line:74]: update job 2021061521220414378611 task 2021061521220414378611_dataio_0 0 status successfully: {'job_id': '2021061521220414378611', 'component_name': 'dataio_0', 'task_id': '2021061521220414378611_dataio_0', 'task_version': '0', 'role': 'guest', 'party_id': '9999', 'run_ip': '127.0.0.1', 'run_pid': 2075, 'party_status': 'failed', 'end_time': 1623792128208, 'elapsed': 510}
[INFO] [2021-06-15 21:22:08,275] [7:140197562341120] - task_scheduler.py[line:143]: job 2021061521220414378611 task 2021061521220414378611_hetero_secure_boost_0 0 status is waiting, calculate by task party status list: ['waiting', 'waiting']
[INFO] [2021-06-15 21:22:08,276] [7:140197562341120] - task_scheduler.py[line:75]: finish scheduling job 2021061521220414378611 tasks
[INFO] [2021-06-15 21:22:08,276] [7:140197562341120] - dag_scheduler.py[line:310]: Job 2021061521220414378611 status is running, calculate by task status list: ['running', 'waiting', 'waiting']
[INFO] [2021-06-15 21:22:08,276] [7:140197562341120] - dag_scheduler.py[line:325]: finish scheduling job 2021061521220414378611
[INFO] [2021-06-15 21:22:08,283] [7:140196188256000] - job_saver.py[line:81]: try to update job 2021061521220414378611 task 2021061521220414378611_dataio_0 0
[INFO] [2021-06-15 21:22:08,286] [7:140198455301888] - job_saver.py[line:84]: job 2021061521220414378611 task 2021061521220414378611_dataio_0 0 update successfully
[INFO] [2021-06-15 21:22:08,298] [7:140198455301888] - job_saver.py[line:71]: try to update job 2021061521220414378611 task 2021061521220414378611_dataio_0 0 status
[INFO] [2021-06-15 21:22:08,307] [7:140196188256000] - job_saver.py[line:84]: job 2021061521220414378611 task 2021061521220414378611_dataio_0 0 update successfully
[INFO] [2021-06-15 21:22:08,313] [7:140196188256000] - job_saver.py[line:71]: try to update job 2021061521220414378611 task 2021061521220414378611_dataio_0 0 status
[INFO] [2021-06-15 21:22:08,327] [7:140198455301888] - job_saver.py[line:74]: update job 2021061521220414378611 task 2021061521220414378611_dataio_0 0 status successfully: {'job_id': '2021061521220414378611', 'component_name': 'dataio_0', 'task_id': '2021061521220414378611_dataio_0', 'task_version': '0', 'role': 'host', 'party_id': '9998', 'run_ip': '127.0.0.1', 'run_pid': 2077, 'party_status': 'failed', 'end_time': 1623792128249, 'elapsed': 543}
[INFO] [2021-06-15 21:22:08,337] [7:140196188256000] - job_saver.py[line:76]: update job 2021061521220414378611 task 2021061521220414378611_dataio_0 0 status update does not take effect: {'job_id': '2021061521220414378611', 'component_name': 'dataio_0', 'task_id': '2021061521220414378611_dataio_0', 'task_version': '0', 'role': 'guest', 'party_id': '9999', 'run_ip': '127.0.0.1', 'run_pid': 2075, 'party_status': 'failed', 'end_time': 1623792128208, 'elapsed': 510}
[INFO] [2021-06-15 21:22:08,353] [7:140196188256000] - job_saver.py[line:81]: try to update job 2021061521220414378611 task 2021061521220414378611_dataio_0 0
[INFO] [2021-06-15 21:22:08,372] [7:140196188256000] - job_saver.py[line:84]: job 2021061521220414378611 task 2021061521220414378611_dataio_0 0 update successfully
[INFO] [2021-06-15 21:22:08,377] [7:140196188256000] - job_saver.py[line:71]: try to update job 2021061521220414378611 task 2021061521220414378611_dataio_0 0 status
[INFO] [2021-06-15 21:22:08,382] [7:140196188256000] - job_saver.py[line:76]: update job 2021061521220414378611 task 2021061521220414378611_dataio_0 0 status update does not take effect: {'job_id': '2021061521220414378611', 'component_name': 'dataio_0', 'task_id': '2021061521220414378611_dataio_0', 'task_version': '0', 'role': 'host', 'party_id': '9998', 'run_ip': '127.0.0.1', 'run_pid': 2077, 'party_status': 'failed', 'end_time': 1623792128249, 'elapsed': 543}
[INFO] [2021-06-15 21:22:10,381] [7:140197562341120] - dag_scheduler.py[line:298]: scheduling job 2021061521220414378611
[INFO] [2021-06-15 21:22:10,396] [7:140197562341120] - task_scheduler.py[line:28]: scheduling job 2021061521220414378611 tasks
[INFO] [2021-06-15 21:22:10,473] [7:140197562341120] - job_saver.py[line:71]: try to update job 2021061521220414378611 task 2021061521220414378611_dataio_0 0 status
[INFO] [2021-06-15 21:22:10,483] [7:140197562341120] - job_saver.py[line:76]: update job 2021061521220414378611 task 2021061521220414378611_dataio_0 0 status update does not take effect: {'elapsed': 510, 'end_time': 1623792128208, 'job_id': '2021061521220414378611', 'party_id': '9999', 'party_status': 'failed', 'role': 'guest', 'start_time': 1623792125911, 'status': 'running', 'task_id': '2021061521220414378611_dataio_0', 'task_version': 0, 'update_time': 1623792124372}
[INFO] [2021-06-15 21:22:10,483] [7:140197562341120] - job_saver.py[line:81]: try to update job 2021061521220414378611 task 2021061521220414378611_dataio_0 0
[INFO] [2021-06-15 21:22:10,502] [7:140197562341120] - job_saver.py[line:84]: job 2021061521220414378611 task 2021061521220414378611_dataio_0 0 update successfully
[INFO] [2021-06-15 21:22:10,502] [7:140197562341120] - job_saver.py[line:71]: try to update job 2021061521220414378611 task 2021061521220414378611_dataio_0 0 status
[INFO] [2021-06-15 21:22:10,509] [7:140197562341120] - job_saver.py[line:76]: update job 2021061521220414378611 task 2021061521220414378611_dataio_0 0 status update does not take effect: {'elapsed': 543, 'end_time': 1623792128249, 'job_id': '2021061521220414378611', 'party_id': '9998', 'party_status': 'failed', 'role': 'host', 'start_time': 1623792126001, 'status': 'running', 'task_id': '2021061521220414378611_dataio_0', 'task_version': 0, 'update_time': 1623792124256}
[INFO] [2021-06-15 21:22:10,509] [7:140197562341120] - job_saver.py[line:81]: try to update job 2021061521220414378611 task 2021061521220414378611_dataio_0 0
[INFO] [2021-06-15 21:22:10,528] [7:140197562341120] - job_saver.py[line:84]: job 2021061521220414378611 task 2021061521220414378611_dataio_0 0 update successfully
[INFO] [2021-06-15 21:22:10,537] [7:140197562341120] - task_scheduler.py[line:143]: job 2021061521220414378611 task 2021061521220414378611_dataio_0 0 status is failed, calculate by task party status list: ['failed', 'failed']
[INFO] [2021-06-15 21:22:10,537] [7:140197562341120] - federated_scheduler.py[line:192]: job 2021061521220414378611 task 2021061521220414378611_dataio_0 0 is failed, sync to all party
[INFO] [2021-06-15 21:22:10,557] [7:140196188256000] - job_saver.py[line:71]: try to update job 2021061521220414378611 task 2021061521220414378611_dataio_0 0 status
[INFO] [2021-06-15 21:22:10,576] [7:140196188256000] - job_saver.py[line:74]: update job 2021061521220414378611 task 2021061521220414378611_dataio_0 0 status successfully: {'job_id': '2021061521220414378611', 'task_id': '2021061521220414378611_dataio_0', 'task_version': '0', 'role': 'guest', 'party_id': '9999', 'status': 'failed'}
[INFO] [2021-06-15 21:22:10,594] [7:140196188256000] - resource_manager.py[line:286]: task 2021061521220414378611_dataio_0 0 return resource successfully
[INFO] [2021-06-15 21:22:10,601] [7:140196188256000] - job_tracker.py[line:424]: clean task 2021061521220414378611_dataio_0 0 on guest 9999
[ERROR] [2021-06-15 21:22:10,603] [7:140196188256000] - job_tracker.py[line:475]: namespace dir /fate/data/2021061521220414378611_dataio_0_0_guest_9999 does not exist
Traceback (most recent call last):
  File "/fate/python/fate_flow/operation/job_tracker.py", line 437, in clean_task
    sess.computing.cleanup(namespace=computing_temp_namespace, name="*")
  File "/fate/python/fate_arch/computing/standalone/_csession.py", line 73, in cleanup
    return self._session.cleanup(name=name, namespace=namespace)
  File "/fate/python/fate_arch/_standalone.py", line 383, in cleanup
    raise EnvironmentError(f"namespace dir {namespace_dir} does not exist")
OSError: namespace dir /fate/data/2021061521220414378611_dataio_0_0_guest_9999 does not exist
[INFO] [2021-06-15 21:22:10,622] [7:140196188256000] - job_saver.py[line:71]: try to update job 2021061521220414378611 task 2021061521220414378611_dataio_0 0 status
[INFO] [2021-06-15 21:22:10,642] [7:140196188256000] - job_saver.py[line:74]: update job 2021061521220414378611 task 2021061521220414378611_dataio_0 0 status successfully: {'job_id': '2021061521220414378611', 'task_id': '2021061521220414378611_dataio_0', 'task_version': '0', 'role': 'host', 'party_id': '9998', 'status': 'failed'}
[INFO] [2021-06-15 21:22:10,660] [7:140196188256000] - resource_manager.py[line:286]: task 2021061521220414378611_dataio_0 0 return resource successfully
[INFO] [2021-06-15 21:22:10,668] [7:140196188256000] - job_tracker.py[line:424]: clean task 2021061521220414378611_dataio_0 0 on host 9998
[ERROR] [2021-06-15 21:22:10,670] [7:140196188256000] - job_tracker.py[line:475]: namespace dir /fate/data/2021061521220414378611_dataio_0_0_host_9998 does not exist
Traceback (most recent call last):
  File "/fate/python/fate_flow/operation/job_tracker.py", line 437, in clean_task
    sess.computing.cleanup(namespace=computing_temp_namespace, name="*")
  File "/fate/python/fate_arch/computing/standalone/_csession.py", line 73, in cleanup
    return self._session.cleanup(name=name, namespace=namespace)
  File "/fate/python/fate_arch/_standalone.py", line 383, in cleanup
    raise EnvironmentError(f"namespace dir {namespace_dir} does not exist")
OSError: namespace dir /fate/data/2021061521220414378611_dataio_0_0_host_9998 does not exist
[INFO] [2021-06-15 21:22:10,684] [7:140197562341120] - federated_scheduler.py[line:195]: sync job 2021061521220414378611 task 2021061521220414378611_dataio_0 0 status failed to all party success
[INFO] [2021-06-15 21:22:10,685] [7:140197562341120] - federated_scheduler.py[line:202]: try to stop job 2021061521220414378611 task 2021061521220414378611_dataio_0 0
[INFO] [2021-06-15 21:22:10,717] [7:140196188256000] - job_utils.py[line:397]: try to stop job 2021061521220414378611 task 2021061521220414378611_dataio_0 guest 9999 with failed party status process pid:2075
[INFO] [2021-06-15 21:22:10,718] [7:140196188256000] - job_utils.py[line:400]: can not found job 2021061521220414378611 task 2021061521220414378611_dataio_0 guest 9999 with failed party status process pid:2075
[INFO] [2021-06-15 21:22:10,722] [7:140196188256000] - job_utils.py[line:424]: start run subprocess to stop task session 2021061521220414378611_dataio_0_0_guest_9999
[INFO] [2021-06-15 21:22:10,723] [7:140196188256000] - job_utils.py[line:310]: start process command: python3 /fate/python/fate_flow/utils/session_utils.py -j 2021061521220414378611_dataio_0_0_guest_9999 --computing STANDALONE --federation STANDALONE --storage STANDALONE -c kill
[INFO] [2021-06-15 21:22:10,734] [7:140196188256000] - job_utils.py[line:334]: start process command: python3 /fate/python/fate_flow/utils/session_utils.py -j 2021061521220414378611_dataio_0_0_guest_9999 --computing STANDALONE --federation STANDALONE --storage STANDALONE -c kill successfully, pid is 2107
[INFO] [2021-06-15 21:22:10,735] [7:140196188256000] - task_controller.py[line:255]: job 2021061521220414378611 task 2021061521220414378611_dataio_0 0 on guest 9999 process 2075 kill success
[INFO] [2021-06-15 21:22:10,735] [7:140196188256000] - job_saver.py[line:71]: try to update job 2021061521220414378611 task 2021061521220414378611_dataio_0 0 status
[INFO] [2021-06-15 21:22:10,746] [7:140196188256000] - job_saver.py[line:76]: update job 2021061521220414378611 task 2021061521220414378611_dataio_0 0 status update does not take effect: {'job_id': '2021061521220414378611', 'task_id': '2021061521220414378611_dataio_0', 'task_version': 0, 'role': 'guest', 'party_id': '9999', 'party_status': 'failed'}
[INFO] [2021-06-15 21:22:10,754] [7:140196188256000] - job_saver.py[line:81]: try to update job 2021061521220414378611 task 2021061521220414378611_dataio_0 0
[WARNING] [2021-06-15 21:22:10,763] [7:140196188256000] - job_saver.py[line:86]: job 2021061521220414378611 task 2021061521220414378611_dataio_0 0 update does not take effect
[INFO] [2021-06-15 21:22:10,797] [7:140196188256000] - job_utils.py[line:397]: try to stop job 2021061521220414378611 task 2021061521220414378611_dataio_0 host 9998 with failed party status process pid:2077
[INFO] [2021-06-15 21:22:10,798] [7:140196188256000] - job_utils.py[line:400]: can not found job 2021061521220414378611 task 2021061521220414378611_dataio_0 host 9998 with failed party status process pid:2077
[INFO] [2021-06-15 21:22:10,803] [7:140196188256000] - job_utils.py[line:424]: start run subprocess to stop task session 2021061521220414378611_dataio_0_0_host_9998
[INFO] [2021-06-15 21:22:10,803] [7:140196188256000] - job_utils.py[line:310]: start process command: python3 /fate/python/fate_flow/utils/session_utils.py -j 2021061521220414378611_dataio_0_0_host_9998 --computing STANDALONE --federation STANDALONE --storage STANDALONE -c kill
[INFO] [2021-06-15 21:22:10,813] [7:140196188256000] - job_utils.py[line:334]: start process command: python3 /fate/python/fate_flow/utils/session_utils.py -j 2021061521220414378611_dataio_0_0_host_9998 --computing STANDALONE --federation STANDALONE --storage STANDALONE -c kill successfully, pid is 2109
[INFO] [2021-06-15 21:22:10,814] [7:140196188256000] - task_controller.py[line:255]: job 2021061521220414378611 task 2021061521220414378611_dataio_0 0 on host 9998 process 2077 kill success
[INFO] [2021-06-15 21:22:10,814] [7:140196188256000] - job_saver.py[line:71]: try to update job 2021061521220414378611 task 2021061521220414378611_dataio_0 0 status
[INFO] [2021-06-15 21:22:10,822] [7:140196188256000] - job_saver.py[line:76]: update job 2021061521220414378611 task 2021061521220414378611_dataio_0 0 status update does not take effect: {'job_id': '2021061521220414378611', 'task_id': '2021061521220414378611_dataio_0', 'task_version': 0, 'role': 'host', 'party_id': '9998', 'party_status': 'failed'}
[INFO] [2021-06-15 21:22:10,829] [7:140196188256000] - job_saver.py[line:81]: try to update job 2021061521220414378611 task 2021061521220414378611_dataio_0 0
[WARNING] [2021-06-15 21:22:10,835] [7:140196188256000] - job_saver.py[line:86]: job 2021061521220414378611 task 2021061521220414378611_dataio_0 0 update does not take effect
[INFO] [2021-06-15 21:22:10,849] [7:140197562341120] - federated_scheduler.py[line:206]: stop job 2021061521220414378611 task 2021061521220414378611_dataio_0 0 success
[INFO] [2021-06-15 21:22:10,866] [7:140197562341120] - task_scheduler.py[line:143]: job 2021061521220414378611 task 2021061521220414378611_intersection_0 0 status is waiting, calculate by task party status list: ['waiting', 'waiting']
[INFO] [2021-06-15 21:22:10,882] [7:140197562341120] - task_scheduler.py[line:143]: job 2021061521220414378611 task 2021061521220414378611_hetero_secure_boost_0 0 status is waiting, calculate by task party status list: ['waiting', 'waiting']
[INFO] [2021-06-15 21:22:10,882] [7:140197562341120] - task_scheduler.py[line:75]: finish scheduling job 2021061521220414378611 tasks
[INFO] [2021-06-15 21:22:10,883] [7:140197562341120] - dag_scheduler.py[line:310]: Job 2021061521220414378611 status is failed, calculate by task status list: ['failed', 'waiting', 'waiting']
[INFO] [2021-06-15 21:22:10,883] [7:140197562341120] - federated_scheduler.py[line:58]: sync job 2021061521220414378611 info to all party
[INFO] [2021-06-15 21:22:10,889] [7:140196188256000] - job_saver.py[line:61]: try to update job 2021061521220414378611
[INFO] [2021-06-15 21:22:10,918] [7:140196188256000] - job_saver.py[line:64]: job 2021061521220414378611 update successfully: {'job_id': '2021061521220414378611', 'role': 'host', 'party_id': '9998', 'progress': 33.33333333333333}
[INFO] [2021-06-15 21:22:10,928] [7:140196188256000] - job_saver.py[line:61]: try to update job 2021061521220414378611
[INFO] [2021-06-15 21:22:10,951] [7:140196188256000] - job_saver.py[line:64]: job 2021061521220414378611 update successfully: {'job_id': '2021061521220414378611', 'role': 'guest', 'party_id': '9999', 'progress': 33.33333333333333}
[INFO] [2021-06-15 21:22:10,954] [7:140197562341120] - federated_scheduler.py[line:61]: sync job 2021061521220414378611 info to all party successfully
[INFO] [2021-06-15 21:22:10,966] [7:140197562341120] - job_saver.py[line:45]: try to update job 2021061521220414378611 status to None
[INFO] [2021-06-15 21:22:10,976] [7:140197562341120] - job_saver.py[line:56]: update job 2021061521220414378611 status does not take effect
[INFO] [2021-06-15 21:22:10,976] [7:140197562341120] - job_saver.py[line:61]: try to update job 2021061521220414378611
[INFO] [2021-06-15 21:22:10,994] [7:140197562341120] - job_saver.py[line:64]: job 2021061521220414378611 update successfully: {'job_id': '2021061521220414378611', 'role': 'host', 'party_id': '9998', 'progress': 33.33333333333333}
[INFO] [2021-06-15 21:22:10,994] [7:140197562341120] - job_saver.py[line:45]: try to update job 2021061521220414378611 status to None
[INFO] [2021-06-15 21:22:11,003] [7:140197562341120] - job_saver.py[line:56]: update job 2021061521220414378611 status does not take effect
[INFO] [2021-06-15 21:22:11,003] [7:140197562341120] - job_saver.py[line:61]: try to update job 2021061521220414378611
[INFO] [2021-06-15 21:22:11,020] [7:140197562341120] - job_saver.py[line:64]: job 2021061521220414378611 update successfully: {'job_id': '2021061521220414378611', 'role': 'guest', 'party_id': '9999', 'progress': 33.33333333333333}
[INFO] [2021-06-15 21:22:11,020] [7:140197562341120] - federated_scheduler.py[line:78]: try to save job 2021061521220414378611 pipelined model
[INFO] [2021-06-15 21:22:11,025] [7:140196188256000] - job_controller.py[line:331]: job 2021061521220414378611 on host 9998 start to save pipeline
[INFO] [2021-06-15 21:22:11,039] [7:140196188256000] - job_controller.py[line:331]: job 2021061521220414378611 on guest 9999 start to save pipeline
[INFO] [2021-06-15 21:22:11,047] [7:140197562341120] - federated_scheduler.py[line:81]: save job 2021061521220414378611 pipelined model success
[INFO] [2021-06-15 21:22:11,048] [7:140197562341120] - federated_scheduler.py[line:68]: job 2021061521220414378611 is failed, sync to all party
[INFO] [2021-06-15 21:22:11,053] [7:140196188256000] - job_saver.py[line:45]: try to update job 2021061521220414378611 status to failed
[INFO] [2021-06-15 21:22:11,068] [7:140196188256000] - job_saver.py[line:48]: update job 2021061521220414378611 status successfully
[INFO] [2021-06-15 21:22:11,100] [7:140196188256000] - resource_manager.py[line:176]: return job 2021061521220414378611 resource(cores 4 memory 0) on host 9998 successfully, remaining cores: 16 remaining memory: 0
[INFO] [2021-06-15 21:22:11,108] [7:140196188256000] - job_saver.py[line:45]: try to update job 2021061521220414378611 status to failed
[INFO] [2021-06-15 21:22:11,490] [7:140196188256000] - job_saver.py[line:48]: update job 2021061521220414378611 status successfully
[INFO] [2021-06-15 21:22:11,505] [2109:140104952407872] - session_utils.py[line:38]: start kill session 2021061521220414378611_dataio_0_0_host_9998
[INFO] [2021-06-15 21:22:11,506] [2109:140104952407872] - session_utils.py[line:47]: kill session 2021061521220414378611_dataio_0_0_host_9998 success
[INFO] [2021-06-15 21:22:11,519] [7:140196188256000] - resource_manager.py[line:176]: return job 2021061521220414378611 resource(cores 4 memory 0) on guest 9999 successfully, remaining cores: 20 remaining memory: 0
[INFO] [2021-06-15 21:22:11,522] [7:140197562341120] - federated_scheduler.py[line:71]: sync job 2021061521220414378611 status failed to all party success
[INFO] [2021-06-15 21:22:11,528] [7:140197562341120] - job_saver.py[line:45]: try to update job 2021061521220414378611 status to failed
[INFO] [2021-06-15 21:22:11,533] [7:140197562341120] - job_saver.py[line:56]: update job 2021061521220414378611 status does not take effect
[INFO] [2021-06-15 21:22:11,534] [7:140197562341120] - job_saver.py[line:61]: try to update job 2021061521220414378611
[WARNING] [2021-06-15 21:22:11,540] [7:140197562341120] - job_saver.py[line:66]: job 2021061521220414378611 update does not take effect: {'job_id': '2021061521220414378611', 'role': 'host', 'party_id': '9998', 'status': 'failed'}
[INFO] [2021-06-15 21:22:11,541] [7:140197562341120] - job_saver.py[line:45]: try to update job 2021061521220414378611 status to failed
[INFO] [2021-06-15 21:22:11,544] [2107:140387568940864] - session_utils.py[line:38]: start kill session 2021061521220414378611_dataio_0_0_guest_9999
[INFO] [2021-06-15 21:22:11,545] [2107:140387568940864] - session_utils.py[line:47]: kill session 2021061521220414378611_dataio_0_0_guest_9999 success
[INFO] [2021-06-15 21:22:11,547] [7:140197562341120] - job_saver.py[line:56]: update job 2021061521220414378611 status does not take effect
[INFO] [2021-06-15 21:22:11,547] [7:140197562341120] - job_saver.py[line:61]: try to update job 2021061521220414378611
[WARNING] [2021-06-15 21:22:11,556] [7:140197562341120] - job_saver.py[line:66]: job 2021061521220414378611 update does not take effect: {'job_id': '2021061521220414378611', 'role': 'guest', 'party_id': '9999', 'status': 'failed'}
[INFO] [2021-06-15 21:22:11,556] [7:140197562341120] - dag_scheduler.py[line:502]: Job 2021061521220414378611 finished with failed, do something...
[INFO] [2021-06-15 21:22:11,557] [7:140197562341120] - dag_scheduler.py[line:436]: request stop job 2021061521220414378611 with failed
[INFO] [2021-06-15 21:22:11,569] [7:140197562341120] - dag_scheduler.py[line:445]: request stop job 2021061521220414378611 with failed to all party
[INFO] [2021-06-15 21:22:11,569] [7:140197562341120] - federated_scheduler.py[line:88]: try to stop job 2021061521220414378611
[INFO] [2021-06-15 21:22:11,587] [7:140196188256000] - job_utils.py[line:393]: job 2021061521220414378611 task 2021061521220414378611_hetero_secure_boost_0 host 9998 with waiting party status no process pid
[INFO] [2021-06-15 21:22:11,587] [7:140196188256000] - task_controller.py[line:255]: job 2021061521220414378611 task 2021061521220414378611_hetero_secure_boost_0 0 on host 9998 process None kill success
[INFO] [2021-06-15 21:22:11,587] [7:140196188256000] - job_saver.py[line:71]: try to update job 2021061521220414378611 task 2021061521220414378611_hetero_secure_boost_0 0 status
[INFO] [2021-06-15 21:22:11,592] [7:140196188256000] - job_saver.py[line:76]: update job 2021061521220414378611 task 2021061521220414378611_hetero_secure_boost_0 0 status update does not take effect: {'job_id': '2021061521220414378611', 'task_id': '2021061521220414378611_hetero_secure_boost_0', 'task_version': 0, 'role': 'host', 'party_id': '9998', 'party_status': 'failed'}
[INFO] [2021-06-15 21:22:11,598] [7:140196188256000] - job_saver.py[line:81]: try to update job 2021061521220414378611 task 2021061521220414378611_hetero_secure_boost_0 0
[WARNING] [2021-06-15 21:22:11,606] [7:140196188256000] - job_saver.py[line:86]: job 2021061521220414378611 task 2021061521220414378611_hetero_secure_boost_0 0 update does not take effect
[INFO] [2021-06-15 21:22:11,612] [7:140196188256000] - job_utils.py[line:393]: job 2021061521220414378611 task 2021061521220414378611_intersection_0 host 9998 with waiting party status no process pid
[INFO] [2021-06-15 21:22:11,612] [7:140196188256000] - task_controller.py[line:255]: job 2021061521220414378611 task 2021061521220414378611_intersection_0 0 on host 9998 process None kill success
[INFO] [2021-06-15 21:22:11,612] [7:140196188256000] - job_saver.py[line:71]: try to update job 2021061521220414378611 task 2021061521220414378611_intersection_0 0 status
[INFO] [2021-06-15 21:22:11,618] [7:140196188256000] - job_saver.py[line:76]: update job 2021061521220414378611 task 2021061521220414378611_intersection_0 0 status update does not take effect: {'job_id': '2021061521220414378611', 'task_id': '2021061521220414378611_intersection_0', 'task_version': 0, 'role': 'host', 'party_id': '9998', 'party_status': 'failed'}
[INFO] [2021-06-15 21:22:11,624] [7:140196188256000] - job_saver.py[line:81]: try to update job 2021061521220414378611 task 2021061521220414378611_intersection_0 0
[WARNING] [2021-06-15 21:22:11,628] [7:140196188256000] - job_saver.py[line:86]: job 2021061521220414378611 task 2021061521220414378611_intersection_0 0 update does not take effect
[INFO] [2021-06-15 21:22:11,633] [7:140196188256000] - job_utils.py[line:397]: try to stop job 2021061521220414378611 task 2021061521220414378611_dataio_0 host 9998 with failed party status process pid:2077
[INFO] [2021-06-15 21:22:11,634] [7:140196188256000] - job_utils.py[line:400]: can not found job 2021061521220414378611 task 2021061521220414378611_dataio_0 host 9998 with failed party status process pid:2077
[INFO] [2021-06-15 21:22:11,637] [7:140196188256000] - job_utils.py[line:424]: start run subprocess to stop task session 2021061521220414378611_dataio_0_0_host_9998
[INFO] [2021-06-15 21:22:11,637] [7:140196188256000] - job_utils.py[line:310]: start process command: python3 /fate/python/fate_flow/utils/session_utils.py -j 2021061521220414378611_dataio_0_0_host_9998 --computing STANDALONE --federation STANDALONE --storage STANDALONE -c kill
[INFO] [2021-06-15 21:22:11,644] [7:140196188256000] - job_utils.py[line:334]: start process command: python3 /fate/python/fate_flow/utils/session_utils.py -j 2021061521220414378611_dataio_0_0_host_9998 --computing STANDALONE --federation STANDALONE --storage STANDALONE -c kill successfully, pid is 2133
[INFO] [2021-06-15 21:22:11,645] [7:140196188256000] - task_controller.py[line:255]: job 2021061521220414378611 task 2021061521220414378611_dataio_0 0 on host 9998 process 2077 kill success
[INFO] [2021-06-15 21:22:11,645] [7:140196188256000] - job_saver.py[line:71]: try to update job 2021061521220414378611 task 2021061521220414378611_dataio_0 0 status
[INFO] [2021-06-15 21:22:11,649] [7:140196188256000] - job_saver.py[line:76]: update job 2021061521220414378611 task 2021061521220414378611_dataio_0 0 status update does not take effect: {'job_id': '2021061521220414378611', 'task_id': '2021061521220414378611_dataio_0', 'task_version': 0, 'role': 'host', 'party_id': '9998', 'party_status': 'failed'}
[INFO] [2021-06-15 21:22:11,654] [7:140196188256000] - job_saver.py[line:81]: try to update job 2021061521220414378611 task 2021061521220414378611_dataio_0 0
[WARNING] [2021-06-15 21:22:11,658] [7:140196188256000] - job_saver.py[line:86]: job 2021061521220414378611 task 2021061521220414378611_dataio_0 0 update does not take effect
[INFO] [2021-06-15 21:22:11,662] [7:140196188256000] - job_saver.py[line:45]: try to update job 2021061521220414378611 status to failed
[INFO] [2021-06-15 21:22:11,668] [7:140196188256000] - job_saver.py[line:56]: update job 2021061521220414378611 status does not take effect
[INFO] [2021-06-15 21:22:11,688] [7:140196188256000] - job_utils.py[line:393]: job 2021061521220414378611 task 2021061521220414378611_hetero_secure_boost_0 guest 9999 with waiting party status no process pid
[INFO] [2021-06-15 21:22:11,688] [7:140196188256000] - task_controller.py[line:255]: job 2021061521220414378611 task 2021061521220414378611_hetero_secure_boost_0 0 on guest 9999 process None kill success
[INFO] [2021-06-15 21:22:11,688] [7:140196188256000] - job_saver.py[line:71]: try to update job 2021061521220414378611 task 2021061521220414378611_hetero_secure_boost_0 0 status
[INFO] [2021-06-15 21:22:11,692] [7:140196188256000] - job_saver.py[line:76]: update job 2021061521220414378611 task 2021061521220414378611_hetero_secure_boost_0 0 status update does not take effect: {'job_id': '2021061521220414378611', 'task_id': '2021061521220414378611_hetero_secure_boost_0', 'task_version': 0, 'role': 'guest', 'party_id': '9999', 'party_status': 'failed'}
[INFO] [2021-06-15 21:22:11,697] [7:140196188256000] - job_saver.py[line:81]: try to update job 2021061521220414378611 task 2021061521220414378611_hetero_secure_boost_0 0
[WARNING] [2021-06-15 21:22:11,703] [7:140196188256000] - job_saver.py[line:86]: job 2021061521220414378611 task 2021061521220414378611_hetero_secure_boost_0 0 update does not take effect
[INFO] [2021-06-15 21:22:11,710] [7:140196188256000] - job_utils.py[line:393]: job 2021061521220414378611 task 2021061521220414378611_intersection_0 guest 9999 with waiting party status no process pid
[INFO] [2021-06-15 21:22:11,710] [7:140196188256000] - task_controller.py[line:255]: job 2021061521220414378611 task 2021061521220414378611_intersection_0 0 on guest 9999 process None kill success
[INFO] [2021-06-15 21:22:11,710] [7:140196188256000] - job_saver.py[line:71]: try to update job 2021061521220414378611 task 2021061521220414378611_intersection_0 0 status
[INFO] [2021-06-15 21:22:11,715] [7:140196188256000] - job_saver.py[line:76]: update job 2021061521220414378611 task 2021061521220414378611_intersection_0 0 status update does not take effect: {'job_id': '2021061521220414378611', 'task_id': '2021061521220414378611_intersection_0', 'task_version': 0, 'role': 'guest', 'party_id': '9999', 'party_status': 'failed'}
[INFO] [2021-06-15 21:22:11,720] [7:140196188256000] - job_saver.py[line:81]: try to update job 2021061521220414378611 task 2021061521220414378611_intersection_0 0
[WARNING] [2021-06-15 21:22:11,726] [7:140196188256000] - job_saver.py[line:86]: job 2021061521220414378611 task 2021061521220414378611_intersection_0 0 update does not take effect
[INFO] [2021-06-15 21:22:11,732] [7:140196188256000] - job_utils.py[line:397]: try to stop job 2021061521220414378611 task 2021061521220414378611_dataio_0 guest 9999 with failed party status process pid:2075
[INFO] [2021-06-15 21:22:11,732] [7:140196188256000] - job_utils.py[line:400]: can not found job 2021061521220414378611 task 2021061521220414378611_dataio_0 guest 9999 with failed party status process pid:2075
[INFO] [2021-06-15 21:22:11,736] [7:140196188256000] - job_utils.py[line:424]: start run subprocess to stop task session 2021061521220414378611_dataio_0_0_guest_9999
[INFO] [2021-06-15 21:22:11,736] [7:140196188256000] - job_utils.py[line:310]: start process command: python3 /fate/python/fate_flow/utils/session_utils.py -j 2021061521220414378611_dataio_0_0_guest_9999 --computing STANDALONE --federation STANDALONE --storage STANDALONE -c kill
[INFO] [2021-06-15 21:22:11,743] [7:140196188256000] - job_utils.py[line:334]: start process command: python3 /fate/python/fate_flow/utils/session_utils.py -j 2021061521220414378611_dataio_0_0_guest_9999 --computing STANDALONE --federation STANDALONE --storage STANDALONE -c kill successfully, pid is 2135
[INFO] [2021-06-15 21:22:11,744] [7:140196188256000] - task_controller.py[line:255]: job 2021061521220414378611 task 2021061521220414378611_dataio_0 0 on guest 9999 process 2075 kill success
[INFO] [2021-06-15 21:22:11,744] [7:140196188256000] - job_saver.py[line:71]: try to update job 2021061521220414378611 task 2021061521220414378611_dataio_0 0 status
[INFO] [2021-06-15 21:22:11,749] [7:140196188256000] - job_saver.py[line:76]: update job 2021061521220414378611 task 2021061521220414378611_dataio_0 0 status update does not take effect: {'job_id': '2021061521220414378611', 'task_id': '2021061521220414378611_dataio_0', 'task_version': 0, 'role': 'guest', 'party_id': '9999', 'party_status': 'failed'}
[INFO] [2021-06-15 21:22:11,755] [7:140196188256000] - job_saver.py[line:81]: try to update job 2021061521220414378611 task 2021061521220414378611_dataio_0 0
[WARNING] [2021-06-15 21:22:11,760] [7:140196188256000] - job_saver.py[line:86]: job 2021061521220414378611 task 2021061521220414378611_dataio_0 0 update does not take effect
[INFO] [2021-06-15 21:22:11,765] [7:140196188256000] - job_saver.py[line:45]: try to update job 2021061521220414378611 status to failed
[INFO] [2021-06-15 21:22:11,775] [7:140196188256000] - job_saver.py[line:56]: update job 2021061521220414378611 status does not take effect
[INFO] [2021-06-15 21:22:11,779] [7:140197562341120] - federated_scheduler.py[line:92]: stop job 2021061521220414378611 success
[INFO] [2021-06-15 21:22:11,779] [7:140197562341120] - dag_scheduler.py[line:448]: stop job 2021061521220414378611 with failed successfully
[INFO] [2021-06-15 21:22:11,779] [7:140197562341120] - federated_scheduler.py[line:107]: try to clean job 2021061521220414378611
[INFO] [2021-06-15 21:22:11,787] [7:140196188256000] - job_controller.py[line:379]: Job 2021061521220414378611 on host 9998 start to clean
[INFO] [2021-06-15 21:22:11,787] [7:140196188256000] - job_controller.py[line:382]: job 2021061521220414378611 on host 9998 clean done
[INFO] [2021-06-15 21:22:11,795] [7:140196188256000] - job_controller.py[line:379]: Job 2021061521220414378611 on guest 9999 start to clean
[INFO] [2021-06-15 21:22:11,795] [7:140196188256000] - job_controller.py[line:382]: job 2021061521220414378611 on guest 9999 clean done
[INFO] [2021-06-15 21:22:11,799] [7:140197562341120] - federated_scheduler.py[line:110]: clean job 2021061521220414378611 success
[INFO] [2021-06-15 21:22:11,799] [7:140197562341120] - dag_scheduler.py[line:505]: Job 2021061521220414378611 finished with failed, done
[INFO] [2021-06-15 21:22:11,800] [7:140197562341120] - dag_scheduler.py[line:325]: finish scheduling job 2021061521220414378611
[INFO] [2021-06-15 21:22:11,843] [7:140197562341120] - dag_scheduler.py[line:298]: scheduling job 2021061521220414378611
[INFO] [2021-06-15 21:22:11,856] [7:140197562341120] - task_scheduler.py[line:28]: scheduling job 2021061521220414378611 tasks
[INFO] [2021-06-15 21:22:11,876] [7:140197562341120] - task_scheduler.py[line:143]: job 2021061521220414378611 task 2021061521220414378611_dataio_0 0 status is failed, calculate by task party status list: ['failed', 'failed']
[INFO] [2021-06-15 21:22:11,888] [7:140197562341120] - task_scheduler.py[line:143]: job 2021061521220414378611 task 2021061521220414378611_intersection_0 0 status is waiting, calculate by task party status list: ['waiting', 'waiting']
[INFO] [2021-06-15 21:22:11,901] [7:140197562341120] - task_scheduler.py[line:143]: job 2021061521220414378611 task 2021061521220414378611_hetero_secure_boost_0 0 status is waiting, calculate by task party status list: ['waiting', 'waiting']
[INFO] [2021-06-15 21:22:11,901] [7:140197562341120] - task_scheduler.py[line:75]: finish scheduling job 2021061521220414378611 tasks
[INFO] [2021-06-15 21:22:11,901] [7:140197562341120] - dag_scheduler.py[line:310]: Job 2021061521220414378611 status is failed, calculate by task status list: ['failed', 'waiting', 'waiting']
[INFO] [2021-06-15 21:22:11,901] [7:140197562341120] - dag_scheduler.py[line:502]: Job 2021061521220414378611 finished with failed, do something...
[INFO] [2021-06-15 21:22:11,901] [7:140197562341120] - dag_scheduler.py[line:436]: request stop job 2021061521220414378611 with failed
[INFO] [2021-06-15 21:22:11,907] [7:140197562341120] - dag_scheduler.py[line:445]: request stop job 2021061521220414378611 with failed to all party
[INFO] [2021-06-15 21:22:11,907] [7:140197562341120] - federated_scheduler.py[line:88]: try to stop job 2021061521220414378611
[INFO] [2021-06-15 21:22:11,922] [7:140196188256000] - job_utils.py[line:393]: job 2021061521220414378611 task 2021061521220414378611_hetero_secure_boost_0 host 9998 with waiting party status no process pid
[INFO] [2021-06-15 21:22:11,922] [7:140196188256000] - task_controller.py[line:255]: job 2021061521220414378611 task 2021061521220414378611_hetero_secure_boost_0 0 on host 9998 process None kill success
[INFO] [2021-06-15 21:22:11,922] [7:140196188256000] - job_saver.py[line:71]: try to update job 2021061521220414378611 task 2021061521220414378611_hetero_secure_boost_0 0 status
[INFO] [2021-06-15 21:22:11,926] [7:140196188256000] - job_saver.py[line:76]: update job 2021061521220414378611 task 2021061521220414378611_hetero_secure_boost_0 0 status update does not take effect: {'job_id': '2021061521220414378611', 'task_id': '2021061521220414378611_hetero_secure_boost_0', 'task_version': 0, 'role': 'host', 'party_id': '9998', 'party_status': 'failed'}
[INFO] [2021-06-15 21:22:11,933] [7:140196188256000] - job_saver.py[line:81]: try to update job 2021061521220414378611 task 2021061521220414378611_hetero_secure_boost_0 0
[WARNING] [2021-06-15 21:22:11,940] [7:140196188256000] - job_saver.py[line:86]: job 2021061521220414378611 task 2021061521220414378611_hetero_secure_boost_0 0 update does not take effect
[INFO] [2021-06-15 21:22:11,949] [7:140196188256000] - job_utils.py[line:393]: job 2021061521220414378611 task 2021061521220414378611_intersection_0 host 9998 with waiting party status no process pid
[INFO] [2021-06-15 21:22:11,950] [7:140196188256000] - task_controller.py[line:255]: job 2021061521220414378611 task 2021061521220414378611_intersection_0 0 on host 9998 process None kill success
[INFO] [2021-06-15 21:22:11,950] [7:140196188256000] - job_saver.py[line:71]: try to update job 2021061521220414378611 task 2021061521220414378611_intersection_0 0 status
[INFO] [2021-06-15 21:22:11,956] [7:140196188256000] - job_saver.py[line:76]: update job 2021061521220414378611 task 2021061521220414378611_intersection_0 0 status update does not take effect: {'job_id': '2021061521220414378611', 'task_id': '2021061521220414378611_intersection_0', 'task_version': 0, 'role': 'host', 'party_id': '9998', 'party_status': 'failed'}
[INFO] [2021-06-15 21:22:11,962] [7:140196188256000] - job_saver.py[line:81]: try to update job 2021061521220414378611 task 2021061521220414378611_intersection_0 0
[WARNING] [2021-06-15 21:22:11,968] [7:140196188256000] - job_saver.py[line:86]: job 2021061521220414378611 task 2021061521220414378611_intersection_0 0 update does not take effect
[INFO] [2021-06-15 21:22:11,974] [7:140196188256000] - job_utils.py[line:397]: try to stop job 2021061521220414378611 task 2021061521220414378611_dataio_0 host 9998 with failed party status process pid:2077
[INFO] [2021-06-15 21:22:11,974] [7:140196188256000] - job_utils.py[line:400]: can not found job 2021061521220414378611 task 2021061521220414378611_dataio_0 host 9998 with failed party status process pid:2077
[INFO] [2021-06-15 21:22:11,977] [7:140196188256000] - job_utils.py[line:424]: start run subprocess to stop task session 2021061521220414378611_dataio_0_0_host_9998
[INFO] [2021-06-15 21:22:11,978] [7:140196188256000] - job_utils.py[line:310]: start process command: python3 /fate/python/fate_flow/utils/session_utils.py -j 2021061521220414378611_dataio_0_0_host_9998 --computing STANDALONE --federation STANDALONE --storage STANDALONE -c kill
[INFO] [2021-06-15 21:22:11,994] [7:140196188256000] - job_utils.py[line:334]: start process command: python3 /fate/python/fate_flow/utils/session_utils.py -j 2021061521220414378611_dataio_0_0_host_9998 --computing STANDALONE --federation STANDALONE --storage STANDALONE -c kill successfully, pid is 2147
[INFO] [2021-06-15 21:22:11,995] [7:140196188256000] - task_controller.py[line:255]: job 2021061521220414378611 task 2021061521220414378611_dataio_0 0 on host 9998 process 2077 kill success
[INFO] [2021-06-15 21:22:11,995] [7:140196188256000] - job_saver.py[line:71]: try to update job 2021061521220414378611 task 2021061521220414378611_dataio_0 0 status
[INFO] [2021-06-15 21:22:12,002] [7:140196188256000] - job_saver.py[line:76]: update job 2021061521220414378611 task 2021061521220414378611_dataio_0 0 status update does not take effect: {'job_id': '2021061521220414378611', 'task_id': '2021061521220414378611_dataio_0', 'task_version': 0, 'role': 'host', 'party_id': '9998', 'party_status': 'failed'}
[INFO] [2021-06-15 21:22:12,012] [7:140196188256000] - job_saver.py[line:81]: try to update job 2021061521220414378611 task 2021061521220414378611_dataio_0 0
[WARNING] [2021-06-15 21:22:12,017] [7:140196188256000] - job_saver.py[line:86]: job 2021061521220414378611 task 2021061521220414378611_dataio_0 0 update does not take effect
[INFO] [2021-06-15 21:22:12,023] [7:140196188256000] - job_saver.py[line:45]: try to update job 2021061521220414378611 status to failed
[INFO] [2021-06-15 21:22:12,031] [7:140196188256000] - job_saver.py[line:56]: update job 2021061521220414378611 status does not take effect
[INFO] [2021-06-15 21:22:12,065] [7:140198455301888] - job_utils.py[line:393]: job 2021061521220414378611 task 2021061521220414378611_hetero_secure_boost_0 guest 9999 with waiting party status no process pid
[INFO] [2021-06-15 21:22:12,066] [7:140198455301888] - task_controller.py[line:255]: job 2021061521220414378611 task 2021061521220414378611_hetero_secure_boost_0 0 on guest 9999 process None kill success
[INFO] [2021-06-15 21:22:12,067] [7:140198455301888] - job_saver.py[line:71]: try to update job 2021061521220414378611 task 2021061521220414378611_hetero_secure_boost_0 0 status
[INFO] [2021-06-15 21:22:12,074] [7:140198455301888] - job_saver.py[line:76]: update job 2021061521220414378611 task 2021061521220414378611_hetero_secure_boost_0 0 status update does not take effect: {'job_id': '2021061521220414378611', 'task_id': '2021061521220414378611_hetero_secure_boost_0', 'task_version': 0, 'role': 'guest', 'party_id': '9999', 'party_status': 'failed'}
[INFO] [2021-06-15 21:22:12,082] [7:140198455301888] - job_saver.py[line:81]: try to update job 2021061521220414378611 task 2021061521220414378611_hetero_secure_boost_0 0
[WARNING] [2021-06-15 21:22:12,090] [7:140198455301888] - job_saver.py[line:86]: job 2021061521220414378611 task 2021061521220414378611_hetero_secure_boost_0 0 update does not take effect
[INFO] [2021-06-15 21:22:12,098] [7:140198455301888] - job_utils.py[line:393]: job 2021061521220414378611 task 2021061521220414378611_intersection_0 guest 9999 with waiting party status no process pid
[INFO] [2021-06-15 21:22:12,098] [7:140198455301888] - task_controller.py[line:255]: job 2021061521220414378611 task 2021061521220414378611_intersection_0 0 on guest 9999 process None kill success
[INFO] [2021-06-15 21:22:12,098] [7:140198455301888] - job_saver.py[line:71]: try to update job 2021061521220414378611 task 2021061521220414378611_intersection_0 0 status
[INFO] [2021-06-15 21:22:12,108] [7:140198455301888] - job_saver.py[line:76]: update job 2021061521220414378611 task 2021061521220414378611_intersection_0 0 status update does not take effect: {'job_id': '2021061521220414378611', 'task_id': '2021061521220414378611_intersection_0', 'task_version': 0, 'role': 'guest', 'party_id': '9999', 'party_status': 'failed'}
[INFO] [2021-06-15 21:22:12,115] [7:140198455301888] - job_saver.py[line:81]: try to update job 2021061521220414378611 task 2021061521220414378611_intersection_0 0
[WARNING] [2021-06-15 21:22:12,124] [7:140198455301888] - job_saver.py[line:86]: job 2021061521220414378611 task 2021061521220414378611_intersection_0 0 update does not take effect
[INFO] [2021-06-15 21:22:12,131] [7:140198455301888] - job_utils.py[line:397]: try to stop job 2021061521220414378611 task 2021061521220414378611_dataio_0 guest 9999 with failed party status process pid:2075
[INFO] [2021-06-15 21:22:12,131] [7:140198455301888] - job_utils.py[line:400]: can not found job 2021061521220414378611 task 2021061521220414378611_dataio_0 guest 9999 with failed party status process pid:2075
[INFO] [2021-06-15 21:22:12,137] [7:140198455301888] - job_utils.py[line:424]: start run subprocess to stop task session 2021061521220414378611_dataio_0_0_guest_9999
[INFO] [2021-06-15 21:22:12,138] [7:140198455301888] - job_utils.py[line:310]: start process command: python3 /fate/python/fate_flow/utils/session_utils.py -j 2021061521220414378611_dataio_0_0_guest_9999 --computing STANDALONE --federation STANDALONE --storage STANDALONE -c kill
[INFO] [2021-06-15 21:22:12,145] [7:140198455301888] - job_utils.py[line:334]: start process command: python3 /fate/python/fate_flow/utils/session_utils.py -j 2021061521220414378611_dataio_0_0_guest_9999 --computing STANDALONE --federation STANDALONE --storage STANDALONE -c kill successfully, pid is 2150
[INFO] [2021-06-15 21:22:12,146] [7:140198455301888] - task_controller.py[line:255]: job 2021061521220414378611 task 2021061521220414378611_dataio_0 0 on guest 9999 process 2075 kill success
[INFO] [2021-06-15 21:22:12,146] [7:140198455301888] - job_saver.py[line:71]: try to update job 2021061521220414378611 task 2021061521220414378611_dataio_0 0 status
[INFO] [2021-06-15 21:22:12,156] [7:140198455301888] - job_saver.py[line:76]: update job 2021061521220414378611 task 2021061521220414378611_dataio_0 0 status update does not take effect: {'job_id': '2021061521220414378611', 'task_id': '2021061521220414378611_dataio_0', 'task_version': 0, 'role': 'guest', 'party_id': '9999', 'party_status': 'failed'}
[INFO] [2021-06-15 21:22:12,164] [7:140198455301888] - job_saver.py[line:81]: try to update job 2021061521220414378611 task 2021061521220414378611_dataio_0 0
[WARNING] [2021-06-15 21:22:12,173] [7:140198455301888] - job_saver.py[line:86]: job 2021061521220414378611 task 2021061521220414378611_dataio_0 0 update does not take effect
[INFO] [2021-06-15 21:22:12,181] [7:140198455301888] - job_saver.py[line:45]: try to update job 2021061521220414378611 status to failed
[INFO] [2021-06-15 21:22:12,188] [7:140198455301888] - job_saver.py[line:56]: update job 2021061521220414378611 status does not take effect
[INFO] [2021-06-15 21:22:12,200] [7:140197562341120] - federated_scheduler.py[line:92]: stop job 2021061521220414378611 success
[INFO] [2021-06-15 21:22:12,200] [7:140197562341120] - dag_scheduler.py[line:448]: stop job 2021061521220414378611 with failed successfully
[INFO] [2021-06-15 21:22:12,200] [7:140197562341120] - federated_scheduler.py[line:107]: try to clean job 2021061521220414378611
[INFO] [2021-06-15 21:22:12,225] [7:140198455301888] - job_controller.py[line:379]: Job 2021061521220414378611 on host 9998 start to clean
[INFO] [2021-06-15 21:22:12,225] [7:140198455301888] - job_controller.py[line:382]: job 2021061521220414378611 on host 9998 clean done
[INFO] [2021-06-15 21:22:12,240] [7:140198455301888] - job_controller.py[line:379]: Job 2021061521220414378611 on guest 9999 start to clean
[INFO] [2021-06-15 21:22:12,240] [7:140198455301888] - job_controller.py[line:382]: job 2021061521220414378611 on guest 9999 clean done
[INFO] [2021-06-15 21:22:12,248] [7:140197562341120] - federated_scheduler.py[line:110]: clean job 2021061521220414378611 success
[INFO] [2021-06-15 21:22:12,248] [7:140197562341120] - dag_scheduler.py[line:505]: Job 2021061521220414378611 finished with failed, done
[INFO] [2021-06-15 21:22:12,248] [7:140197562341120] - dag_scheduler.py[line:325]: finish scheduling job 2021061521220414378611
[INFO] [2021-06-15 21:22:12,532] [2133:139697777534784] - session_utils.py[line:38]: start kill session 2021061521220414378611_dataio_0_0_host_9998
[INFO] [2021-06-15 21:22:12,534] [2133:139697777534784] - session_utils.py[line:47]: kill session 2021061521220414378611_dataio_0_0_host_9998 success
[INFO] [2021-06-15 21:22:12,727] [2135:140033415309120] - session_utils.py[line:38]: start kill session 2021061521220414378611_dataio_0_0_guest_9999
[INFO] [2021-06-15 21:22:12,728] [2135:140033415309120] - session_utils.py[line:47]: kill session 2021061521220414378611_dataio_0_0_guest_9999 success
[INFO] [2021-06-15 21:22:12,854] [2147:139810952791872] - session_utils.py[line:38]: start kill session 2021061521220414378611_dataio_0_0_host_9998
[INFO] [2021-06-15 21:22:12,855] [2147:139810952791872] - session_utils.py[line:47]: kill session 2021061521220414378611_dataio_0_0_host_9998 success
[INFO] [2021-06-15 21:22:12,916] [2150:140015163680576] - session_utils.py[line:38]: start kill session 2021061521220414378611_dataio_0_0_guest_9999
[INFO] [2021-06-15 21:22:12,917] [2150:140015163680576] - session_utils.py[line:47]: kill session 2021061521220414378611_dataio_0_0_guest_9999 success
[INFO] [2021-06-15 21:22:14,473] [7:140197562341120] - dag_scheduler.py[line:193]: the number of updates has been exceeded
[INFO] [2021-06-15 21:22:16,537] [7:140197562341120] - dag_scheduler.py[line:193]: the number of updates has been exceeded
[INFO] [2021-06-15 21:22:18,592] [7:140197562341120] - dag_scheduler.py[line:193]: the number of updates has been exceeded
[INFO] [2021-06-15 21:22:20,653] [7:140197562341120] - dag_scheduler.py[line:193]: the number of updates has been exceeded
[INFO] [2021-06-15 21:22:22,711] [7:140197562341120] - dag_scheduler.py[line:193]: the number of updates has been exceeded
[INFO] [2021-06-15 21:22:24,776] [7:140197562341120] - dag_scheduler.py[line:193]: the number of updates has been exceeded
[INFO] [2021-06-15 21:22:26,825] [7:140197562341120] - dag_scheduler.py[line:193]: the number of updates has been exceeded
[INFO] [2021-06-15 21:22:28,885] [7:140197562341120] - dag_scheduler.py[line:193]: the number of updates has been exceeded
[INFO] [2021-06-15 21:22:31,471] [7:140197562341120] - dag_scheduler.py[line:193]: the number of updates has been exceeded
[INFO] [2021-06-15 21:22:33,699] [7:140197562341120] - dag_scheduler.py[line:193]: the number of updates has been exceeded
[INFO] [2021-06-15 21:22:37,416] [7:140197562341120] - dag_scheduler.py[line:193]: the number of updates has been exceeded
[INFO] [2021-06-15 21:22:39,900] [7:140197562341120] - dag_scheduler.py[line:193]: the number of updates has been exceeded
[INFO] [2021-06-15 21:22:41,974] [7:140197562341120] - dag_scheduler.py[line:193]: the number of updates has been exceeded
[INFO] [2021-06-15 21:22:44,048] [7:140197562341120] - dag_scheduler.py[line:193]: the number of updates has been exceeded
[INFO] [2021-06-15 21:22:46,109] [7:140197562341120] - dag_scheduler.py[line:193]: the number of updates has been exceeded
[INFO] [2021-06-15 21:22:48,211] [7:140197562341120] - dag_scheduler.py[line:193]: the number of updates has been exceeded
[INFO] [2021-06-15 21:22:50,271] [7:140197562341120] - dag_scheduler.py[line:193]: the number of updates has been exceeded
[INFO] [2021-06-15 21:22:52,354] [7:140197562341120] - dag_scheduler.py[line:193]: the number of updates has been exceeded
[INFO] [2021-06-15 21:22:54,413] [7:140197562341120] - dag_scheduler.py[line:193]: the number of updates has been exceeded
[INFO] [2021-06-15 21:22:56,469] [7:140197562341120] - dag_scheduler.py[line:193]: the number of updates has been exceeded
[INFO] [2021-06-15 21:22:58,523] [7:140197562341120] - dag_scheduler.py[line:193]: the number of updates has been exceeded
[INFO] [2021-06-15 21:23:00,562] [7:140197562341120] - dag_scheduler.py[line:193]: the number of updates has been exceeded
[INFO] [2021-06-15 21:23:02,614] [7:140197562341120] - dag_scheduler.py[line:193]: the number of updates has been exceeded
[INFO] [2021-06-15 21:23:04,678] [7:140197562341120] - dag_scheduler.py[line:193]: the number of updates has been exceeded
[INFO] [2021-06-15 21:23:06,739] [7:140197562341120] - dag_scheduler.py[line:193]: the number of updates has been exceeded
[INFO] [2021-06-15 21:23:08,788] [7:140197562341120] - dag_scheduler.py[line:193]: the number of updates has been exceeded
[INFO] [2021-06-15 21:23:10,847] [7:140197562341120] - dag_scheduler.py[line:193]: the number of updates has been exceeded
[INFO] [2021-06-15 21:23:12,902] [7:140197562341120] - dag_scheduler.py[line:193]: the number of updates has been exceeded
[INFO] [2021-06-15 21:23:14,953] [7:140197562341120] - dag_scheduler.py[line:193]: the number of updates has been exceeded
[INFO] [2021-06-15 21:23:17,001] [7:140197562341120] - dag_scheduler.py[line:193]: the number of updates has been exceeded
[INFO] [2021-06-15 21:23:19,051] [7:140197562341120] - dag_scheduler.py[line:193]: the number of updates has been exceeded
[INFO] [2021-06-15 21:23:21,106] [7:140197562341120] - dag_scheduler.py[line:193]: the number of updates has been exceeded
[INFO] [2021-06-15 21:23:23,157] [7:140197562341120] - dag_scheduler.py[line:193]: the number of updates has been exceeded
[INFO] [2021-06-15 21:23:25,218] [7:140197562341120] - dag_scheduler.py[line:193]: the number of updates has been exceeded
[INFO] [2021-06-15 21:23:27,264] [7:140197562341120] - dag_scheduler.py[line:193]: the number of updates has been exceeded
[INFO] [2021-06-15 21:23:29,323] [7:140197562341120] - dag_scheduler.py[line:193]: the number of updates has been exceeded
[INFO] [2021-06-15 21:23:31,380] [7:140197562341120] - dag_scheduler.py[line:193]: the number of updates has been exceeded
[INFO] [2021-06-15 21:23:33,458] [7:140197562341120] - dag_scheduler.py[line:193]: the number of updates has been exceeded
[INFO] [2021-06-15 21:23:35,549] [7:140197562341120] - dag_scheduler.py[line:193]: the number of updates has been exceeded
[INFO] [2021-06-15 21:23:37,604] [7:140197562341120] - dag_scheduler.py[line:193]: the number of updates has been exceeded
[INFO] [2021-06-15 21:23:39,657] [7:140197562341120] - dag_scheduler.py[line:193]: the number of updates has been exceeded
[INFO] [2021-06-15 21:23:41,748] [7:140197562341120] - dag_scheduler.py[line:193]: the number of updates has been exceeded
[INFO] [2021-06-15 21:23:43,811] [7:140197562341120] - dag_scheduler.py[line:193]: the number of updates has been exceeded
[INFO] [2021-06-15 21:23:45,852] [7:140197562341120] - dag_scheduler.py[line:193]: the number of updates has been exceeded
[INFO] [2021-06-15 21:23:47,905] [7:140197562341120] - dag_scheduler.py[line:193]: the number of updates has been exceeded
[INFO] [2021-06-15 21:23:49,954] [7:140197562341120] - dag_scheduler.py[line:193]: the number of updates has been exceeded
[INFO] [2021-06-15 21:23:52,006] [7:140197562341120] - dag_scheduler.py[line:193]: the number of updates has been exceeded
[INFO] [2021-06-15 21:23:54,058] [7:140197562341120] - dag_scheduler.py[line:193]: the number of updates has been exceeded
[INFO] [2021-06-15 21:23:56,109] [7:140197562341120] - dag_scheduler.py[line:193]: the number of updates has been exceeded
[INFO] [2021-06-15 21:23:58,165] [7:140197562341120] - dag_scheduler.py[line:193]: the number of updates has been exceeded
[INFO] [2021-06-15 21:24:00,242] [7:140197562341120] - dag_scheduler.py[line:193]: the number of updates has been exceeded
[INFO] [2021-06-15 21:24:02,297] [7:140197562341120] - dag_scheduler.py[line:193]: the number of updates has been exceeded
[INFO] [2021-06-15 21:24:04,349] [7:140197562341120] - dag_scheduler.py[line:193]: the number of updates has been exceeded
[INFO] [2021-06-15 21:24:06,394] [7:140197562341120] - dag_scheduler.py[line:193]: the number of updates has been exceeded
[INFO] [2021-06-15 21:24:08,469] [7:140197562341120] - dag_scheduler.py[line:193]: the number of updates has been exceeded
[INFO] [2021-06-15 21:24:10,525] [7:140197562341120] - dag_scheduler.py[line:193]: the number of updates has been exceeded
[INFO] [2021-06-15 21:24:12,579] [7:140197562341120] - dag_scheduler.py[line:193]: the number of updates has been exceeded
[INFO] [2021-06-15 21:24:14,638] [7:140197562341120] - dag_scheduler.py[line:193]: the number of updates has been exceeded
[INFO] [2021-06-15 21:24:16,689] [7:140197562341120] - dag_scheduler.py[line:193]: the number of updates has been exceeded
[INFO] [2021-06-15 21:24:18,757] [7:140197562341120] - dag_scheduler.py[line:193]: the number of updates has been exceeded
[INFO] [2021-06-15 21:24:20,835] [7:140197562341120] - dag_scheduler.py[line:193]: the number of updates has been exceeded
[INFO] [2021-06-15 21:24:22,898] [7:140197562341120] - dag_scheduler.py[line:193]: the number of updates has been exceeded
[INFO] [2021-06-15 21:24:24,958] [7:140197562341120] - dag_scheduler.py[line:193]: the number of updates has been exceeded
[INFO] [2021-06-15 21:24:27,016] [7:140197562341120] - dag_scheduler.py[line:193]: the number of updates has been exceeded
[INFO] [2021-06-15 21:24:29,077] [7:140197562341120] - dag_scheduler.py[line:193]: the number of updates has been exceeded
[INFO] [2021-06-15 21:24:31,133] [7:140197562341120] - dag_scheduler.py[line:193]: the number of updates has been exceeded
[INFO] [2021-06-15 21:24:33,185] [7:140197562341120] - dag_scheduler.py[line:193]: the number of updates has been exceeded
[INFO] [2021-06-15 21:24:35,241] [7:140197562341120] - dag_scheduler.py[line:193]: the number of updates has been exceeded
[INFO] [2021-06-15 21:24:37,301] [7:140197562341120] - dag_scheduler.py[line:193]: the number of updates has been exceeded
[INFO] [2021-06-15 21:24:39,352] [7:140197562341120] - dag_scheduler.py[line:193]: the number of updates has been exceeded
[INFO] [2021-06-15 21:24:41,408] [7:140197562341120] - dag_scheduler.py[line:193]: the number of updates has been exceeded
[INFO] [2021-06-15 21:24:43,462] [7:140197562341120] - dag_scheduler.py[line:193]: the number of updates has been exceeded
[INFO] [2021-06-15 21:24:45,522] [7:140197562341120] - dag_scheduler.py[line:193]: the number of updates has been exceeded
[INFO] [2021-06-15 21:24:47,574] [7:140197562341120] - dag_scheduler.py[line:193]: the number of updates has been exceeded
[INFO] [2021-06-15 21:24:49,623] [7:140197562341120] - dag_scheduler.py[line:193]: the number of updates has been exceeded
[INFO] [2021-06-15 21:24:51,664] [7:140197562341120] - dag_scheduler.py[line:193]: the number of updates has been exceeded
[INFO] [2021-06-15 21:24:53,716] [7:140197562341120] - dag_scheduler.py[line:193]: the number of updates has been exceeded
[INFO] [2021-06-15 21:24:55,767] [7:140197562341120] - dag_scheduler.py[line:193]: the number of updates has been exceeded
[INFO] [2021-06-15 21:24:57,803] [7:140197562341120] - dag_scheduler.py[line:193]: the number of updates has been exceeded
[INFO] [2021-06-15 21:24:59,861] [7:140197562341120] - dag_scheduler.py[line:193]: the number of updates has been exceeded
[INFO] [2021-06-15 21:25:01,919] [7:140197562341120] - dag_scheduler.py[line:193]: the number of updates has been exceeded
[INFO] [2021-06-15 21:25:03,971] [7:140197562341120] - dag_scheduler.py[line:193]: the number of updates has been exceeded
[INFO] [2021-06-15 21:25:06,022] [7:140197562341120] - dag_scheduler.py[line:193]: the number of updates has been exceeded
[INFO] [2021-06-15 21:25:08,073] [7:140197562341120] - dag_scheduler.py[line:193]: the number of updates has been exceeded
[INFO] [2021-06-15 21:25:10,124] [7:140197562341120] - dag_scheduler.py[line:193]: the number of updates has been exceeded
[INFO] [2021-06-15 21:25:12,193] [7:140197562341120] - dag_scheduler.py[line:193]: the number of updates has been exceeded
[INFO] [2021-06-15 21:25:14,254] [7:140197562341120] - dag_scheduler.py[line:193]: the number of updates has been exceeded
[INFO] [2021-06-15 21:25:16,305] [7:140197562341120] - dag_scheduler.py[line:193]: the number of updates has been exceeded
[INFO] [2021-06-15 21:25:18,356] [7:140197562341120] - dag_scheduler.py[line:193]: the number of updates has been exceeded
[INFO] [2021-06-15 21:25:20,409] [7:140197562341120] - dag_scheduler.py[line:193]: the number of updates has been exceeded
[INFO] [2021-06-15 21:25:22,462] [7:140197562341120] - dag_scheduler.py[line:193]: the number of updates has been exceeded
[INFO] [2021-06-15 21:25:24,515] [7:140197562341120] - dag_scheduler.py[line:193]: the number of updates has been exceeded
[INFO] [2021-06-15 21:25:26,551] [7:140197562341120] - dag_scheduler.py[line:193]: the number of updates has been exceeded
[INFO] [2021-06-15 21:25:28,611] [7:140197562341120] - dag_scheduler.py[line:193]: the number of updates has been exceeded
[INFO] [2021-06-15 21:25:30,665] [7:140197562341120] - dag_scheduler.py[line:193]: the number of updates has been exceeded
[INFO] [2021-06-15 21:25:32,742] [7:140197562341120] - dag_scheduler.py[line:193]: the number of updates has been exceeded
[INFO] [2021-06-15 21:25:34,791] [7:140197562341120] - dag_scheduler.py[line:193]: the number of updates has been exceeded
[INFO] [2021-06-15 21:25:36,841] [7:140197562341120] - dag_scheduler.py[line:193]: the number of updates has been exceeded
[INFO] [2021-06-15 21:25:38,893] [7:140197562341120] - dag_scheduler.py[line:193]: the number of updates has been exceeded
[INFO] [2021-06-15 21:25:40,946] [7:140197562341120] - dag_scheduler.py[line:193]: the number of updates has been exceeded
[INFO] [2021-06-15 21:25:42,996] [7:140197562341120] - dag_scheduler.py[line:193]: the number of updates has been exceeded
[INFO] [2021-06-15 21:25:45,053] [7:140197562341120] - dag_scheduler.py[line:193]: the number of updates has been exceeded
[INFO] [2021-06-15 21:25:47,116] [7:140197562341120] - dag_scheduler.py[line:193]: the number of updates has been exceeded
[INFO] [2021-06-15 21:25:49,169] [7:140197562341120] - dag_scheduler.py[line:193]: the number of updates has been exceeded
[INFO] [2021-06-15 21:25:51,208] [7:140197562341120] - dag_scheduler.py[line:193]: the number of updates has been exceeded
[INFO] [2021-06-15 21:25:53,254] [7:140197562341120] - dag_scheduler.py[line:193]: the number of updates has been exceeded
[INFO] [2021-06-15 21:25:55,318] [7:140197562341120] - dag_scheduler.py[line:193]: the number of updates has been exceeded
[INFO] [2021-06-15 21:25:57,375] [7:140197562341120] - dag_scheduler.py[line:193]: the number of updates has been exceeded
[INFO] [2021-06-15 21:25:59,425] [7:140197562341120] - dag_scheduler.py[line:193]: the number of updates has been exceeded
[INFO] [2021-06-15 21:26:01,478] [7:140197562341120] - dag_scheduler.py[line:193]: the number of updates has been exceeded
[INFO] [2021-06-15 21:26:03,537] [7:140197562341120] - dag_scheduler.py[line:193]: the number of updates has been exceeded
[INFO] [2021-06-15 21:26:05,587] [7:140197562341120] - dag_scheduler.py[line:193]: the number of updates has been exceeded
[INFO] [2021-06-15 21:26:07,639] [7:140197562341120] - dag_scheduler.py[line:193]: the number of updates has been exceeded
[INFO] [2021-06-15 21:26:09,682] [7:140197562341120] - dag_scheduler.py[line:193]: the number of updates has been exceeded
[INFO] [2021-06-15 21:26:11,722] [7:140197562341120] - dag_scheduler.py[line:193]: the number of updates has been exceeded
[INFO] [2021-06-15 21:26:13,774] [7:140197562341120] - dag_scheduler.py[line:193]: the number of updates has been exceeded
[INFO] [2021-06-15 21:26:15,824] [7:140197562341120] - dag_scheduler.py[line:193]: the number of updates has been exceeded
[INFO] [2021-06-15 21:26:17,877] [7:140197562341120] - dag_scheduler.py[line:193]: the number of updates has been exceeded
[INFO] [2021-06-15 21:26:19,929] [7:140197562341120] - dag_scheduler.py[line:193]: the number of updates has been exceeded
[INFO] [2021-06-15 21:26:21,982] [7:140197562341120] - dag_scheduler.py[line:193]: the number of updates has been exceeded
[INFO] [2021-06-15 21:26:24,036] [7:140197562341120] - dag_scheduler.py[line:193]: the number of updates has been exceeded
[INFO] [2021-06-15 21:26:26,091] [7:140197562341120] - dag_scheduler.py[line:193]: the number of updates has been exceeded
[INFO] [2021-06-15 21:26:28,144] [7:140197562341120] - dag_scheduler.py[line:193]: the number of updates has been exceeded
[INFO] [2021-06-15 21:26:30,186] [7:140197562341120] - dag_scheduler.py[line:193]: the number of updates has been exceeded
[INFO] [2021-06-15 21:26:32,217] [7:140197562341120] - dag_scheduler.py[line:193]: the number of updates has been exceeded
[INFO] [2021-06-15 21:26:34,286] [7:140197562341120] - dag_scheduler.py[line:193]: the number of updates has been exceeded
[INFO] [2021-06-15 21:26:36,331] [7:140197562341120] - dag_scheduler.py[line:193]: the number of updates has been exceeded
[INFO] [2021-06-15 21:26:38,381] [7:140197562341120] - dag_scheduler.py[line:193]: the number of updates has been exceeded
[INFO] [2021-06-15 21:26:40,463] [7:140197562341120] - dag_scheduler.py[line:193]: the number of updates has been exceeded
[INFO] [2021-06-15 21:26:42,516] [7:140197562341120] - dag_scheduler.py[line:193]: the number of updates has been exceeded
[INFO] [2021-06-15 21:26:44,569] [7:140197562341120] - dag_scheduler.py[line:193]: the number of updates has been exceeded
[INFO] [2021-06-15 21:26:46,625] [7:140197562341120] - dag_scheduler.py[line:193]: the number of updates has been exceeded
[INFO] [2021-06-15 21:26:49,268] [7:140197562341120] - dag_scheduler.py[line:193]: the number of updates has been exceeded
[INFO] [2021-06-15 21:26:52,413] [7:140197562341120] - dag_scheduler.py[line:193]: the number of updates has been exceeded
[INFO] [2021-06-15 21:26:54,814] [7:140197562341120] - dag_scheduler.py[line:193]: the number of updates has been exceeded
[INFO] [2021-06-15 21:26:56,872] [7:140197562341120] - dag_scheduler.py[line:193]: the number of updates has been exceeded
[INFO] [2021-06-15 21:26:58,939] [7:140197562341120] - dag_scheduler.py[line:193]: the number of updates has been exceeded
[INFO] [2021-06-15 21:27:00,999] [7:140197562341120] - dag_scheduler.py[line:193]: the number of updates has been exceeded
[INFO] [2021-06-15 21:27:03,056] [7:140197562341120] - dag_scheduler.py[line:193]: the number of updates has been exceeded
[INFO] [2021-06-15 21:27:05,111] [7:140197562341120] - dag_scheduler.py[line:193]: the number of updates has been exceeded
[INFO] [2021-06-15 21:27:07,167] [7:140197562341120] - dag_scheduler.py[line:193]: the number of updates has been exceeded
[INFO] [2021-06-15 21:27:09,220] [7:140197562341120] - dag_scheduler.py[line:193]: the number of updates has been exceeded
[INFO] [2021-06-15 21:27:11,277] [7:140197562341120] - dag_scheduler.py[line:193]: the number of updates has been exceeded
