[ERROR] [2021-06-13 11:53:13,289] [8:139726518462208] - api_utils.py[line:49]: BusyError: database is locked
Traceback (most recent call last):
  File "/usr/local/lib/python3.6/site-packages/flask/app.py", line 2292, in wsgi_app
    response = self.full_dispatch_request()
  File "/usr/local/lib/python3.6/site-packages/flask/app.py", line 1815, in full_dispatch_request
    rv = self.handle_user_exception(e)
  File "/usr/local/lib/python3.6/site-packages/flask/app.py", line 1718, in handle_user_exception
    reraise(exc_type, exc_value, tb)
  File "/usr/local/lib/python3.6/site-packages/flask/_compat.py", line 35, in reraise
    raise value
  File "/usr/local/lib/python3.6/site-packages/flask/app.py", line 1813, in full_dispatch_request
    rv = self.dispatch_request()
  File "/usr/local/lib/python3.6/site-packages/flask/app.py", line 1799, in dispatch_request
    return self.view_functions[rule.endpoint](**req.view_args)
  File "/fate/python/fate_flow/apps/job_app.py", line 94, in query_job
    jobs = JobSaver.query_job(**request.json)
  File "/usr/local/lib/python3.6/site-packages/peewee.py", line 394, in inner
    return fn(*args, **kwargs)
  File "/fate/python/fate_flow/operation/job_saver.py", line 219, in query_job
    return [job for job in jobs]
  File "/usr/local/lib/python3.6/site-packages/peewee.py", line 6246, in __iter__
    self.execute()
  File "/usr/local/lib/python3.6/site-packages/peewee.py", line 1737, in inner
    return method(self, database, *args, **kwargs)
  File "/usr/local/lib/python3.6/site-packages/peewee.py", line 1808, in execute
    return self._execute(database)
  File "/usr/local/lib/python3.6/site-packages/peewee.py", line 1982, in _execute
    cursor = database.execute(self)
  File "/usr/local/lib/python3.6/site-packages/peewee.py", line 2888, in execute
    return self.execute_sql(sql, params, commit=commit)
  File "/usr/local/lib/python3.6/site-packages/playhouse/apsw_ext.py", line 112, in execute_sql
    cursor.execute(sql, params or ())
  File "src/cursor.c", line 1019, in APSWCursor_execute.sqlite3_prepare
  File "src/statementcache.c", line 386, in sqlite3_prepare
apsw.BusyError: BusyError: database is locked
[ERROR] [2021-06-13 17:02:14,037] [8:139727092389632] - model_app.py[line:51]: Deploy model failed, no model guest-10000#host-10000#model 202106131701058277089 found.
Traceback (most recent call last):
  File "/usr/local/lib/python3.6/site-packages/flask/app.py", line 2292, in wsgi_app
    response = self.full_dispatch_request()
  File "/usr/local/lib/python3.6/site-packages/flask/app.py", line 1815, in full_dispatch_request
    rv = self.handle_user_exception(e)
  File "/usr/local/lib/python3.6/site-packages/flask/app.py", line 1718, in handle_user_exception
    reraise(exc_type, exc_value, tb)
  File "/usr/local/lib/python3.6/site-packages/flask/_compat.py", line 35, in reraise
    raise value
  File "/usr/local/lib/python3.6/site-packages/flask/app.py", line 1813, in full_dispatch_request
    rv = self.dispatch_request()
  File "/usr/local/lib/python3.6/site-packages/flask/app.py", line 1799, in dispatch_request
    return self.view_functions[rule.endpoint](**req.view_args)
  File "/fate/python/fate_flow/apps/model_app.py", line 603, in deploy
    raise Exception(f'Deploy model failed, no model {model_id} {model_version} found.')
Exception: Deploy model failed, no model guest-10000#host-10000#model 202106131701058277089 found.
[ERROR] [2021-06-13 17:44:43,175] [7:139672735213312] - api_utils.py[line:49]: [Errno 2] No such file or directory: '/fate/model_local_cache/guest#10000#guest-10000#host-9999#model/20200928174750711017114/define/define_meta.yaml'
Traceback (most recent call last):
  File "/usr/local/lib/python3.6/site-packages/flask/app.py", line 2292, in wsgi_app
    response = self.full_dispatch_request()
  File "/usr/local/lib/python3.6/site-packages/flask/app.py", line 1815, in full_dispatch_request
    rv = self.handle_user_exception(e)
  File "/usr/local/lib/python3.6/site-packages/flask/app.py", line 1718, in handle_user_exception
    reraise(exc_type, exc_value, tb)
  File "/usr/local/lib/python3.6/site-packages/flask/_compat.py", line 35, in reraise
    raise value
  File "/usr/local/lib/python3.6/site-packages/flask/app.py", line 1813, in full_dispatch_request
    rv = self.dispatch_request()
  File "/usr/local/lib/python3.6/site-packages/flask/app.py", line 1799, in dispatch_request
    return self.view_functions[rule.endpoint](**req.view_args)
  File "/fate/python/fate_flow/apps/job_app.py", line 50, in submit_job
    submit_result = DAGScheduler.submit(request.json)
  File "/fate/python/fate_flow/scheduler/dag_scheduler.py", line 61, in submit
    pipeline_model = tracker.get_output_model('pipeline')
  File "/fate/python/fate_flow/operation/job_tracker.py", line 188, in get_output_model
    model_alias=model_alias)
  File "/fate/python/fate_flow/pipelined_model/pipelined_model.py", line 83, in read_component_model
    model_alias=model_alias)
  File "/fate/python/fate_flow/pipelined_model/pipelined_model.py", line 165, in get_model_proto_index
    with open(self.define_meta_path, "r", encoding="utf-8") as fr:
FileNotFoundError: [Errno 2] No such file or directory: '/fate/model_local_cache/guest#10000#guest-10000#host-9999#model/20200928174750711017114/define/define_meta.yaml'
[ERROR] [2021-06-13 17:46:55,272] [7:139673186752256] - tracking_app.py[line:43]: SQLError: no such table: t_tracking_output_data_info_20210613
Traceback (most recent call last):
  File "/usr/local/lib/python3.6/site-packages/flask/app.py", line 2292, in wsgi_app
    response = self.full_dispatch_request()
  File "/usr/local/lib/python3.6/site-packages/flask/app.py", line 1815, in full_dispatch_request
    rv = self.handle_user_exception(e)
  File "/usr/local/lib/python3.6/site-packages/flask/app.py", line 1718, in handle_user_exception
    reraise(exc_type, exc_value, tb)
  File "/usr/local/lib/python3.6/site-packages/flask/_compat.py", line 35, in reraise
    raise value
  File "/usr/local/lib/python3.6/site-packages/flask/app.py", line 1813, in full_dispatch_request
    rv = self.dispatch_request()
  File "/usr/local/lib/python3.6/site-packages/flask/app.py", line 1799, in dispatch_request
    return self.view_functions[rule.endpoint](**req.view_args)
  File "/fate/python/fate_flow/apps/tracking_app.py", line 216, in component_output_data
    output_tables_meta = get_component_output_tables_meta(task_data=request_data)
  File "/fate/python/fate_flow/apps/tracking_app.py", line 377, in get_component_output_tables_meta
    output_data_table_infos = tracker.get_output_data_info()
  File "/fate/python/fate_flow/operation/job_tracker.py", line 381, in get_output_data_info
    return self.read_output_data_info_from_db(data_name=data_name)
  File "/fate/python/fate_flow/operation/job_tracker.py", line 391, in read_output_data_info_from_db
    return self.query_output_data_infos(**filter_dict)
  File "/usr/local/lib/python3.6/site-packages/peewee.py", line 394, in inner
    return fn(*args, **kwargs)
  File "/fate/python/fate_flow/operation/job_tracker.py", line 408, in query_output_data_infos
    for output_data_info in output_data_infos_tmp:
  File "/usr/local/lib/python3.6/site-packages/peewee.py", line 6246, in __iter__
    self.execute()
  File "/usr/local/lib/python3.6/site-packages/peewee.py", line 1737, in inner
    return method(self, database, *args, **kwargs)
  File "/usr/local/lib/python3.6/site-packages/peewee.py", line 1808, in execute
    return self._execute(database)
  File "/usr/local/lib/python3.6/site-packages/peewee.py", line 1982, in _execute
    cursor = database.execute(self)
  File "/usr/local/lib/python3.6/site-packages/peewee.py", line 2888, in execute
    return self.execute_sql(sql, params, commit=commit)
  File "/usr/local/lib/python3.6/site-packages/playhouse/apsw_ext.py", line 112, in execute_sql
    cursor.execute(sql, params or ())
  File "src/cursor.c", line 1019, in APSWCursor_execute.sqlite3_prepare
  File "src/statementcache.c", line 386, in sqlite3_prepare
apsw.SQLError: SQLError: no such table: t_tracking_output_data_info_20210613
[ERROR] [2021-06-13 17:46:58,521] [7:139672025802496] - initiator_app.py[line:32]: Create <Model: Task> failed:
ConstraintError: UNIQUE constraint failed: t_task.f_job_id, t_task.f_task_id, t_task.f_task_version, t_task.f_role, t_task.f_party_id
Traceback (most recent call last):
  File "/usr/local/lib/python3.6/site-packages/playhouse/apsw_ext.py", line 112, in execute_sql
    cursor.execute(sql, params or ())
  File "src/cursor.c", line 236, in resetcursor
apsw.ConstraintError: ConstraintError: UNIQUE constraint failed: t_task.f_job_id, t_task.f_task_id, t_task.f_task_version, t_task.f_role, t_task.f_party_id

During handling of the above exception, another exception occurred:

Traceback (most recent call last):
  File "/fate/python/fate_flow/operation/job_saver.py", line 99, in create_job_family_entity
    rows = obj.save(force_insert=True)
  File "/fate/python/fate_arch/storage/metastore/base_model.py", line 89, in save
    return super(BaseModel, self).save(*args, **kwargs)
  File "/usr/local/lib/python3.6/site-packages/peewee.py", line 5964, in save
    self.insert(**field_dict).execute()
  File "/usr/local/lib/python3.6/site-packages/peewee.py", line 1737, in inner
    return method(self, database, *args, **kwargs)
  File "/usr/local/lib/python3.6/site-packages/peewee.py", line 1808, in execute
    return self._execute(database)
  File "/usr/local/lib/python3.6/site-packages/peewee.py", line 2512, in _execute
    return super(Insert, self)._execute(database)
  File "/usr/local/lib/python3.6/site-packages/peewee.py", line 2275, in _execute
    cursor = database.execute(self)
  File "/usr/local/lib/python3.6/site-packages/peewee.py", line 2888, in execute
    return self.execute_sql(sql, params, commit=commit)
  File "/usr/local/lib/python3.6/site-packages/playhouse/apsw_ext.py", line 112, in execute_sql
    cursor.execute(sql, params or ())
  File "/usr/local/lib/python3.6/site-packages/peewee.py", line 2666, in __exit__
    reraise(new_type, new_type(*exc_args), traceback)
  File "/usr/local/lib/python3.6/site-packages/peewee.py", line 179, in reraise
    raise value.with_traceback(tb)
  File "/usr/local/lib/python3.6/site-packages/playhouse/apsw_ext.py", line 112, in execute_sql
    cursor.execute(sql, params or ())
  File "src/cursor.c", line 236, in resetcursor
peewee.IntegrityError: ConstraintError: UNIQUE constraint failed: t_task.f_job_id, t_task.f_task_id, t_task.f_task_version, t_task.f_role, t_task.f_party_id

During handling of the above exception, another exception occurred:

Traceback (most recent call last):
  File "/usr/local/lib/python3.6/site-packages/flask/app.py", line 2292, in wsgi_app
    response = self.full_dispatch_request()
  File "/usr/local/lib/python3.6/site-packages/flask/app.py", line 1815, in full_dispatch_request
    rv = self.handle_user_exception(e)
  File "/usr/local/lib/python3.6/site-packages/flask/app.py", line 1718, in handle_user_exception
    reraise(exc_type, exc_value, tb)
  File "/usr/local/lib/python3.6/site-packages/flask/_compat.py", line 35, in reraise
    raise value
  File "/usr/local/lib/python3.6/site-packages/flask/app.py", line 1813, in full_dispatch_request
    rv = self.dispatch_request()
  File "/usr/local/lib/python3.6/site-packages/flask/app.py", line 1799, in dispatch_request
    return self.view_functions[rule.endpoint](**req.view_args)
  File "/fate/python/fate_flow/scheduling_apps/initiator_app.py", line 48, in rerun_job
    component_name=request.json.get("component_name"))
  File "/fate/python/fate_flow/scheduler/dag_scheduler.py", line 363, in rerun_job
    JobController.initialize_tasks(job_id, _role, _party_id, False, job.f_initiator_role, job.f_initiator_party_id, RunParameters(**job.f_runtime_conf_on_party["job_parameters"]), dsl_parser, component_name=task.f_component_name, task_version=task.f_task_version)
  File "/fate/python/fate_flow/controller/job_controller.py", line 192, in initialize_tasks
    role=role, party_id=party_id, run_on_this_party=run_on_this_party, task_info=task_info)
  File "/fate/python/fate_flow/controller/task_controller.py", line 52, in create_task
    JobSaver.create_task(task_info=task_info)
  File "/fate/python/fate_flow/operation/job_saver.py", line 36, in create_task
    return cls.create_job_family_entity(Task, task_info)
  File "/usr/local/lib/python3.6/site-packages/peewee.py", line 394, in inner
    return fn(*args, **kwargs)
  File "/fate/python/fate_flow/operation/job_saver.py", line 107, in create_job_family_entity
    raise Exception("Create {} failed:\n{}".format(entity_model, e))
Exception: Create <Model: Task> failed:
ConstraintError: UNIQUE constraint failed: t_task.f_job_id, t_task.f_task_id, t_task.f_task_version, t_task.f_role, t_task.f_party_id
[ERROR] [2021-06-13 17:47:00,904] [7:139672025802496] - tracking_app.py[line:43]: SQLError: no such table: t_tracking_output_data_info_20210613
Traceback (most recent call last):
  File "/usr/local/lib/python3.6/site-packages/flask/app.py", line 2292, in wsgi_app
    response = self.full_dispatch_request()
  File "/usr/local/lib/python3.6/site-packages/flask/app.py", line 1815, in full_dispatch_request
    rv = self.handle_user_exception(e)
  File "/usr/local/lib/python3.6/site-packages/flask/app.py", line 1718, in handle_user_exception
    reraise(exc_type, exc_value, tb)
  File "/usr/local/lib/python3.6/site-packages/flask/_compat.py", line 35, in reraise
    raise value
  File "/usr/local/lib/python3.6/site-packages/flask/app.py", line 1813, in full_dispatch_request
    rv = self.dispatch_request()
  File "/usr/local/lib/python3.6/site-packages/flask/app.py", line 1799, in dispatch_request
    return self.view_functions[rule.endpoint](**req.view_args)
  File "/fate/python/fate_flow/apps/tracking_app.py", line 216, in component_output_data
    output_tables_meta = get_component_output_tables_meta(task_data=request_data)
  File "/fate/python/fate_flow/apps/tracking_app.py", line 377, in get_component_output_tables_meta
    output_data_table_infos = tracker.get_output_data_info()
  File "/fate/python/fate_flow/operation/job_tracker.py", line 381, in get_output_data_info
    return self.read_output_data_info_from_db(data_name=data_name)
  File "/fate/python/fate_flow/operation/job_tracker.py", line 391, in read_output_data_info_from_db
    return self.query_output_data_infos(**filter_dict)
  File "/usr/local/lib/python3.6/site-packages/peewee.py", line 394, in inner
    return fn(*args, **kwargs)
  File "/fate/python/fate_flow/operation/job_tracker.py", line 408, in query_output_data_infos
    for output_data_info in output_data_infos_tmp:
  File "/usr/local/lib/python3.6/site-packages/peewee.py", line 6246, in __iter__
    self.execute()
  File "/usr/local/lib/python3.6/site-packages/peewee.py", line 1737, in inner
    return method(self, database, *args, **kwargs)
  File "/usr/local/lib/python3.6/site-packages/peewee.py", line 1808, in execute
    return self._execute(database)
  File "/usr/local/lib/python3.6/site-packages/peewee.py", line 1982, in _execute
    cursor = database.execute(self)
  File "/usr/local/lib/python3.6/site-packages/peewee.py", line 2888, in execute
    return self.execute_sql(sql, params, commit=commit)
  File "/usr/local/lib/python3.6/site-packages/playhouse/apsw_ext.py", line 112, in execute_sql
    cursor.execute(sql, params or ())
  File "src/cursor.c", line 1019, in APSWCursor_execute.sqlite3_prepare
  File "src/statementcache.c", line 386, in sqlite3_prepare
apsw.SQLError: SQLError: no such table: t_tracking_output_data_info_20210613
[ERROR] [2021-06-13 17:47:06,620] [7:139672025802496] - tracking_app.py[line:43]: SQLError: no such table: t_tracking_output_data_info_20210613
Traceback (most recent call last):
  File "/usr/local/lib/python3.6/site-packages/flask/app.py", line 2292, in wsgi_app
    response = self.full_dispatch_request()
  File "/usr/local/lib/python3.6/site-packages/flask/app.py", line 1815, in full_dispatch_request
    rv = self.handle_user_exception(e)
  File "/usr/local/lib/python3.6/site-packages/flask/app.py", line 1718, in handle_user_exception
    reraise(exc_type, exc_value, tb)
  File "/usr/local/lib/python3.6/site-packages/flask/_compat.py", line 35, in reraise
    raise value
  File "/usr/local/lib/python3.6/site-packages/flask/app.py", line 1813, in full_dispatch_request
    rv = self.dispatch_request()
  File "/usr/local/lib/python3.6/site-packages/flask/app.py", line 1799, in dispatch_request
    return self.view_functions[rule.endpoint](**req.view_args)
  File "/fate/python/fate_flow/apps/tracking_app.py", line 216, in component_output_data
    output_tables_meta = get_component_output_tables_meta(task_data=request_data)
  File "/fate/python/fate_flow/apps/tracking_app.py", line 377, in get_component_output_tables_meta
    output_data_table_infos = tracker.get_output_data_info()
  File "/fate/python/fate_flow/operation/job_tracker.py", line 381, in get_output_data_info
    return self.read_output_data_info_from_db(data_name=data_name)
  File "/fate/python/fate_flow/operation/job_tracker.py", line 391, in read_output_data_info_from_db
    return self.query_output_data_infos(**filter_dict)
  File "/usr/local/lib/python3.6/site-packages/peewee.py", line 394, in inner
    return fn(*args, **kwargs)
  File "/fate/python/fate_flow/operation/job_tracker.py", line 408, in query_output_data_infos
    for output_data_info in output_data_infos_tmp:
  File "/usr/local/lib/python3.6/site-packages/peewee.py", line 6246, in __iter__
    self.execute()
  File "/usr/local/lib/python3.6/site-packages/peewee.py", line 1737, in inner
    return method(self, database, *args, **kwargs)
  File "/usr/local/lib/python3.6/site-packages/peewee.py", line 1808, in execute
    return self._execute(database)
  File "/usr/local/lib/python3.6/site-packages/peewee.py", line 1982, in _execute
    cursor = database.execute(self)
  File "/usr/local/lib/python3.6/site-packages/peewee.py", line 2888, in execute
    return self.execute_sql(sql, params, commit=commit)
  File "/usr/local/lib/python3.6/site-packages/playhouse/apsw_ext.py", line 112, in execute_sql
    cursor.execute(sql, params or ())
  File "src/cursor.c", line 1019, in APSWCursor_execute.sqlite3_prepare
  File "src/statementcache.c", line 386, in sqlite3_prepare
apsw.SQLError: SQLError: no such table: t_tracking_output_data_info_20210613
[ERROR] [2021-06-13 17:47:10,999] [7:139672025802496] - tracking_app.py[line:43]: SQLError: no such table: t_tracking_output_data_info_20210613
Traceback (most recent call last):
  File "/usr/local/lib/python3.6/site-packages/flask/app.py", line 2292, in wsgi_app
    response = self.full_dispatch_request()
  File "/usr/local/lib/python3.6/site-packages/flask/app.py", line 1815, in full_dispatch_request
    rv = self.handle_user_exception(e)
  File "/usr/local/lib/python3.6/site-packages/flask/app.py", line 1718, in handle_user_exception
    reraise(exc_type, exc_value, tb)
  File "/usr/local/lib/python3.6/site-packages/flask/_compat.py", line 35, in reraise
    raise value
  File "/usr/local/lib/python3.6/site-packages/flask/app.py", line 1813, in full_dispatch_request
    rv = self.dispatch_request()
  File "/usr/local/lib/python3.6/site-packages/flask/app.py", line 1799, in dispatch_request
    return self.view_functions[rule.endpoint](**req.view_args)
  File "/fate/python/fate_flow/apps/tracking_app.py", line 216, in component_output_data
    output_tables_meta = get_component_output_tables_meta(task_data=request_data)
  File "/fate/python/fate_flow/apps/tracking_app.py", line 377, in get_component_output_tables_meta
    output_data_table_infos = tracker.get_output_data_info()
  File "/fate/python/fate_flow/operation/job_tracker.py", line 381, in get_output_data_info
    return self.read_output_data_info_from_db(data_name=data_name)
  File "/fate/python/fate_flow/operation/job_tracker.py", line 391, in read_output_data_info_from_db
    return self.query_output_data_infos(**filter_dict)
  File "/usr/local/lib/python3.6/site-packages/peewee.py", line 394, in inner
    return fn(*args, **kwargs)
  File "/fate/python/fate_flow/operation/job_tracker.py", line 408, in query_output_data_infos
    for output_data_info in output_data_infos_tmp:
  File "/usr/local/lib/python3.6/site-packages/peewee.py", line 6246, in __iter__
    self.execute()
  File "/usr/local/lib/python3.6/site-packages/peewee.py", line 1737, in inner
    return method(self, database, *args, **kwargs)
  File "/usr/local/lib/python3.6/site-packages/peewee.py", line 1808, in execute
    return self._execute(database)
  File "/usr/local/lib/python3.6/site-packages/peewee.py", line 1982, in _execute
    cursor = database.execute(self)
  File "/usr/local/lib/python3.6/site-packages/peewee.py", line 2888, in execute
    return self.execute_sql(sql, params, commit=commit)
  File "/usr/local/lib/python3.6/site-packages/playhouse/apsw_ext.py", line 112, in execute_sql
    cursor.execute(sql, params or ())
  File "src/cursor.c", line 1019, in APSWCursor_execute.sqlite3_prepare
  File "src/statementcache.c", line 386, in sqlite3_prepare
apsw.SQLError: SQLError: no such table: t_tracking_output_data_info_20210613
[ERROR] [2021-06-13 17:47:47,209] [7:139672025802496] - tracking_app.py[line:43]: SQLError: no such table: t_tracking_output_data_info_20210613
Traceback (most recent call last):
  File "/usr/local/lib/python3.6/site-packages/flask/app.py", line 2292, in wsgi_app
    response = self.full_dispatch_request()
  File "/usr/local/lib/python3.6/site-packages/flask/app.py", line 1815, in full_dispatch_request
    rv = self.handle_user_exception(e)
  File "/usr/local/lib/python3.6/site-packages/flask/app.py", line 1718, in handle_user_exception
    reraise(exc_type, exc_value, tb)
  File "/usr/local/lib/python3.6/site-packages/flask/_compat.py", line 35, in reraise
    raise value
  File "/usr/local/lib/python3.6/site-packages/flask/app.py", line 1813, in full_dispatch_request
    rv = self.dispatch_request()
  File "/usr/local/lib/python3.6/site-packages/flask/app.py", line 1799, in dispatch_request
    return self.view_functions[rule.endpoint](**req.view_args)
  File "/fate/python/fate_flow/apps/tracking_app.py", line 216, in component_output_data
    output_tables_meta = get_component_output_tables_meta(task_data=request_data)
  File "/fate/python/fate_flow/apps/tracking_app.py", line 377, in get_component_output_tables_meta
    output_data_table_infos = tracker.get_output_data_info()
  File "/fate/python/fate_flow/operation/job_tracker.py", line 381, in get_output_data_info
    return self.read_output_data_info_from_db(data_name=data_name)
  File "/fate/python/fate_flow/operation/job_tracker.py", line 391, in read_output_data_info_from_db
    return self.query_output_data_infos(**filter_dict)
  File "/usr/local/lib/python3.6/site-packages/peewee.py", line 394, in inner
    return fn(*args, **kwargs)
  File "/fate/python/fate_flow/operation/job_tracker.py", line 408, in query_output_data_infos
    for output_data_info in output_data_infos_tmp:
  File "/usr/local/lib/python3.6/site-packages/peewee.py", line 6246, in __iter__
    self.execute()
  File "/usr/local/lib/python3.6/site-packages/peewee.py", line 1737, in inner
    return method(self, database, *args, **kwargs)
  File "/usr/local/lib/python3.6/site-packages/peewee.py", line 1808, in execute
    return self._execute(database)
  File "/usr/local/lib/python3.6/site-packages/peewee.py", line 1982, in _execute
    cursor = database.execute(self)
  File "/usr/local/lib/python3.6/site-packages/peewee.py", line 2888, in execute
    return self.execute_sql(sql, params, commit=commit)
  File "/usr/local/lib/python3.6/site-packages/playhouse/apsw_ext.py", line 112, in execute_sql
    cursor.execute(sql, params or ())
  File "src/cursor.c", line 1019, in APSWCursor_execute.sqlite3_prepare
  File "src/statementcache.c", line 386, in sqlite3_prepare
apsw.SQLError: SQLError: no such table: t_tracking_output_data_info_20210613
[ERROR] [2021-06-13 17:47:52,022] [7:139672025802496] - tracking_app.py[line:43]: SQLError: no such table: t_tracking_output_data_info_20210613
Traceback (most recent call last):
  File "/usr/local/lib/python3.6/site-packages/flask/app.py", line 2292, in wsgi_app
    response = self.full_dispatch_request()
  File "/usr/local/lib/python3.6/site-packages/flask/app.py", line 1815, in full_dispatch_request
    rv = self.handle_user_exception(e)
  File "/usr/local/lib/python3.6/site-packages/flask/app.py", line 1718, in handle_user_exception
    reraise(exc_type, exc_value, tb)
  File "/usr/local/lib/python3.6/site-packages/flask/_compat.py", line 35, in reraise
    raise value
  File "/usr/local/lib/python3.6/site-packages/flask/app.py", line 1813, in full_dispatch_request
    rv = self.dispatch_request()
  File "/usr/local/lib/python3.6/site-packages/flask/app.py", line 1799, in dispatch_request
    return self.view_functions[rule.endpoint](**req.view_args)
  File "/fate/python/fate_flow/apps/tracking_app.py", line 216, in component_output_data
    output_tables_meta = get_component_output_tables_meta(task_data=request_data)
  File "/fate/python/fate_flow/apps/tracking_app.py", line 377, in get_component_output_tables_meta
    output_data_table_infos = tracker.get_output_data_info()
  File "/fate/python/fate_flow/operation/job_tracker.py", line 381, in get_output_data_info
    return self.read_output_data_info_from_db(data_name=data_name)
  File "/fate/python/fate_flow/operation/job_tracker.py", line 391, in read_output_data_info_from_db
    return self.query_output_data_infos(**filter_dict)
  File "/usr/local/lib/python3.6/site-packages/peewee.py", line 394, in inner
    return fn(*args, **kwargs)
  File "/fate/python/fate_flow/operation/job_tracker.py", line 408, in query_output_data_infos
    for output_data_info in output_data_infos_tmp:
  File "/usr/local/lib/python3.6/site-packages/peewee.py", line 6246, in __iter__
    self.execute()
  File "/usr/local/lib/python3.6/site-packages/peewee.py", line 1737, in inner
    return method(self, database, *args, **kwargs)
  File "/usr/local/lib/python3.6/site-packages/peewee.py", line 1808, in execute
    return self._execute(database)
  File "/usr/local/lib/python3.6/site-packages/peewee.py", line 1982, in _execute
    cursor = database.execute(self)
  File "/usr/local/lib/python3.6/site-packages/peewee.py", line 2888, in execute
    return self.execute_sql(sql, params, commit=commit)
  File "/usr/local/lib/python3.6/site-packages/playhouse/apsw_ext.py", line 112, in execute_sql
    cursor.execute(sql, params or ())
  File "src/cursor.c", line 1019, in APSWCursor_execute.sqlite3_prepare
  File "src/statementcache.c", line 386, in sqlite3_prepare
apsw.SQLError: SQLError: no such table: t_tracking_output_data_info_20210613
[ERROR] [2021-06-13 17:48:14,791] [7:139672894609152] - tracking_app.py[line:43]: SQLError: no such table: t_tracking_output_data_info_20210613
Traceback (most recent call last):
  File "/usr/local/lib/python3.6/site-packages/flask/app.py", line 2292, in wsgi_app
    response = self.full_dispatch_request()
  File "/usr/local/lib/python3.6/site-packages/flask/app.py", line 1815, in full_dispatch_request
    rv = self.handle_user_exception(e)
  File "/usr/local/lib/python3.6/site-packages/flask/app.py", line 1718, in handle_user_exception
    reraise(exc_type, exc_value, tb)
  File "/usr/local/lib/python3.6/site-packages/flask/_compat.py", line 35, in reraise
    raise value
  File "/usr/local/lib/python3.6/site-packages/flask/app.py", line 1813, in full_dispatch_request
    rv = self.dispatch_request()
  File "/usr/local/lib/python3.6/site-packages/flask/app.py", line 1799, in dispatch_request
    return self.view_functions[rule.endpoint](**req.view_args)
  File "/fate/python/fate_flow/apps/tracking_app.py", line 216, in component_output_data
    output_tables_meta = get_component_output_tables_meta(task_data=request_data)
  File "/fate/python/fate_flow/apps/tracking_app.py", line 377, in get_component_output_tables_meta
    output_data_table_infos = tracker.get_output_data_info()
  File "/fate/python/fate_flow/operation/job_tracker.py", line 381, in get_output_data_info
    return self.read_output_data_info_from_db(data_name=data_name)
  File "/fate/python/fate_flow/operation/job_tracker.py", line 391, in read_output_data_info_from_db
    return self.query_output_data_infos(**filter_dict)
  File "/usr/local/lib/python3.6/site-packages/peewee.py", line 394, in inner
    return fn(*args, **kwargs)
  File "/fate/python/fate_flow/operation/job_tracker.py", line 408, in query_output_data_infos
    for output_data_info in output_data_infos_tmp:
  File "/usr/local/lib/python3.6/site-packages/peewee.py", line 6246, in __iter__
    self.execute()
  File "/usr/local/lib/python3.6/site-packages/peewee.py", line 1737, in inner
    return method(self, database, *args, **kwargs)
  File "/usr/local/lib/python3.6/site-packages/peewee.py", line 1808, in execute
    return self._execute(database)
  File "/usr/local/lib/python3.6/site-packages/peewee.py", line 1982, in _execute
    cursor = database.execute(self)
  File "/usr/local/lib/python3.6/site-packages/peewee.py", line 2888, in execute
    return self.execute_sql(sql, params, commit=commit)
  File "/usr/local/lib/python3.6/site-packages/playhouse/apsw_ext.py", line 112, in execute_sql
    cursor.execute(sql, params or ())
  File "src/cursor.c", line 1019, in APSWCursor_execute.sqlite3_prepare
  File "src/statementcache.c", line 386, in sqlite3_prepare
apsw.SQLError: SQLError: no such table: t_tracking_output_data_info_20210613
[ERROR] [2021-06-13 17:49:41,038] [7:139671011038976] - tracking_app.py[line:43]: SQLError: no such table: t_tracking_output_data_info_20210613
Traceback (most recent call last):
  File "/usr/local/lib/python3.6/site-packages/flask/app.py", line 2292, in wsgi_app
    response = self.full_dispatch_request()
  File "/usr/local/lib/python3.6/site-packages/flask/app.py", line 1815, in full_dispatch_request
    rv = self.handle_user_exception(e)
  File "/usr/local/lib/python3.6/site-packages/flask/app.py", line 1718, in handle_user_exception
    reraise(exc_type, exc_value, tb)
  File "/usr/local/lib/python3.6/site-packages/flask/_compat.py", line 35, in reraise
    raise value
  File "/usr/local/lib/python3.6/site-packages/flask/app.py", line 1813, in full_dispatch_request
    rv = self.dispatch_request()
  File "/usr/local/lib/python3.6/site-packages/flask/app.py", line 1799, in dispatch_request
    return self.view_functions[rule.endpoint](**req.view_args)
  File "/fate/python/fate_flow/apps/tracking_app.py", line 216, in component_output_data
    output_tables_meta = get_component_output_tables_meta(task_data=request_data)
  File "/fate/python/fate_flow/apps/tracking_app.py", line 377, in get_component_output_tables_meta
    output_data_table_infos = tracker.get_output_data_info()
  File "/fate/python/fate_flow/operation/job_tracker.py", line 381, in get_output_data_info
    return self.read_output_data_info_from_db(data_name=data_name)
  File "/fate/python/fate_flow/operation/job_tracker.py", line 391, in read_output_data_info_from_db
    return self.query_output_data_infos(**filter_dict)
  File "/usr/local/lib/python3.6/site-packages/peewee.py", line 394, in inner
    return fn(*args, **kwargs)
  File "/fate/python/fate_flow/operation/job_tracker.py", line 408, in query_output_data_infos
    for output_data_info in output_data_infos_tmp:
  File "/usr/local/lib/python3.6/site-packages/peewee.py", line 6246, in __iter__
    self.execute()
  File "/usr/local/lib/python3.6/site-packages/peewee.py", line 1737, in inner
    return method(self, database, *args, **kwargs)
  File "/usr/local/lib/python3.6/site-packages/peewee.py", line 1808, in execute
    return self._execute(database)
  File "/usr/local/lib/python3.6/site-packages/peewee.py", line 1982, in _execute
    cursor = database.execute(self)
  File "/usr/local/lib/python3.6/site-packages/peewee.py", line 2888, in execute
    return self.execute_sql(sql, params, commit=commit)
  File "/usr/local/lib/python3.6/site-packages/playhouse/apsw_ext.py", line 112, in execute_sql
    cursor.execute(sql, params or ())
  File "src/cursor.c", line 1019, in APSWCursor_execute.sqlite3_prepare
  File "src/statementcache.c", line 386, in sqlite3_prepare
apsw.SQLError: SQLError: no such table: t_tracking_output_data_info_20210613
[ERROR] [2021-06-13 17:50:22,362] [7:139672894609152] - tracking_app.py[line:43]: SQLError: no such table: t_tracking_output_data_info_20210613
Traceback (most recent call last):
  File "/usr/local/lib/python3.6/site-packages/flask/app.py", line 2292, in wsgi_app
    response = self.full_dispatch_request()
  File "/usr/local/lib/python3.6/site-packages/flask/app.py", line 1815, in full_dispatch_request
    rv = self.handle_user_exception(e)
  File "/usr/local/lib/python3.6/site-packages/flask/app.py", line 1718, in handle_user_exception
    reraise(exc_type, exc_value, tb)
  File "/usr/local/lib/python3.6/site-packages/flask/_compat.py", line 35, in reraise
    raise value
  File "/usr/local/lib/python3.6/site-packages/flask/app.py", line 1813, in full_dispatch_request
    rv = self.dispatch_request()
  File "/usr/local/lib/python3.6/site-packages/flask/app.py", line 1799, in dispatch_request
    return self.view_functions[rule.endpoint](**req.view_args)
  File "/fate/python/fate_flow/apps/tracking_app.py", line 216, in component_output_data
    output_tables_meta = get_component_output_tables_meta(task_data=request_data)
  File "/fate/python/fate_flow/apps/tracking_app.py", line 377, in get_component_output_tables_meta
    output_data_table_infos = tracker.get_output_data_info()
  File "/fate/python/fate_flow/operation/job_tracker.py", line 381, in get_output_data_info
    return self.read_output_data_info_from_db(data_name=data_name)
  File "/fate/python/fate_flow/operation/job_tracker.py", line 391, in read_output_data_info_from_db
    return self.query_output_data_infos(**filter_dict)
  File "/usr/local/lib/python3.6/site-packages/peewee.py", line 394, in inner
    return fn(*args, **kwargs)
  File "/fate/python/fate_flow/operation/job_tracker.py", line 408, in query_output_data_infos
    for output_data_info in output_data_infos_tmp:
  File "/usr/local/lib/python3.6/site-packages/peewee.py", line 6246, in __iter__
    self.execute()
  File "/usr/local/lib/python3.6/site-packages/peewee.py", line 1737, in inner
    return method(self, database, *args, **kwargs)
  File "/usr/local/lib/python3.6/site-packages/peewee.py", line 1808, in execute
    return self._execute(database)
  File "/usr/local/lib/python3.6/site-packages/peewee.py", line 1982, in _execute
    cursor = database.execute(self)
  File "/usr/local/lib/python3.6/site-packages/peewee.py", line 2888, in execute
    return self.execute_sql(sql, params, commit=commit)
  File "/usr/local/lib/python3.6/site-packages/playhouse/apsw_ext.py", line 112, in execute_sql
    cursor.execute(sql, params or ())
  File "src/cursor.c", line 1019, in APSWCursor_execute.sqlite3_prepare
  File "src/statementcache.c", line 386, in sqlite3_prepare
apsw.SQLError: SQLError: no such table: t_tracking_output_data_info_20210613
[ERROR] [2021-06-13 17:50:27,770] [7:139672894609152] - tracking_app.py[line:43]: SQLError: no such table: t_tracking_output_data_info_20210613
Traceback (most recent call last):
  File "/usr/local/lib/python3.6/site-packages/flask/app.py", line 2292, in wsgi_app
    response = self.full_dispatch_request()
  File "/usr/local/lib/python3.6/site-packages/flask/app.py", line 1815, in full_dispatch_request
    rv = self.handle_user_exception(e)
  File "/usr/local/lib/python3.6/site-packages/flask/app.py", line 1718, in handle_user_exception
    reraise(exc_type, exc_value, tb)
  File "/usr/local/lib/python3.6/site-packages/flask/_compat.py", line 35, in reraise
    raise value
  File "/usr/local/lib/python3.6/site-packages/flask/app.py", line 1813, in full_dispatch_request
    rv = self.dispatch_request()
  File "/usr/local/lib/python3.6/site-packages/flask/app.py", line 1799, in dispatch_request
    return self.view_functions[rule.endpoint](**req.view_args)
  File "/fate/python/fate_flow/apps/tracking_app.py", line 216, in component_output_data
    output_tables_meta = get_component_output_tables_meta(task_data=request_data)
  File "/fate/python/fate_flow/apps/tracking_app.py", line 377, in get_component_output_tables_meta
    output_data_table_infos = tracker.get_output_data_info()
  File "/fate/python/fate_flow/operation/job_tracker.py", line 381, in get_output_data_info
    return self.read_output_data_info_from_db(data_name=data_name)
  File "/fate/python/fate_flow/operation/job_tracker.py", line 391, in read_output_data_info_from_db
    return self.query_output_data_infos(**filter_dict)
  File "/usr/local/lib/python3.6/site-packages/peewee.py", line 394, in inner
    return fn(*args, **kwargs)
  File "/fate/python/fate_flow/operation/job_tracker.py", line 408, in query_output_data_infos
    for output_data_info in output_data_infos_tmp:
  File "/usr/local/lib/python3.6/site-packages/peewee.py", line 6246, in __iter__
    self.execute()
  File "/usr/local/lib/python3.6/site-packages/peewee.py", line 1737, in inner
    return method(self, database, *args, **kwargs)
  File "/usr/local/lib/python3.6/site-packages/peewee.py", line 1808, in execute
    return self._execute(database)
  File "/usr/local/lib/python3.6/site-packages/peewee.py", line 1982, in _execute
    cursor = database.execute(self)
  File "/usr/local/lib/python3.6/site-packages/peewee.py", line 2888, in execute
    return self.execute_sql(sql, params, commit=commit)
  File "/usr/local/lib/python3.6/site-packages/playhouse/apsw_ext.py", line 112, in execute_sql
    cursor.execute(sql, params or ())
  File "src/cursor.c", line 1019, in APSWCursor_execute.sqlite3_prepare
  File "src/statementcache.c", line 386, in sqlite3_prepare
apsw.SQLError: SQLError: no such table: t_tracking_output_data_info_20210613
[ERROR] [2021-06-13 17:50:55,145] [7:139671019431680] - tracking_app.py[line:43]: SQLError: no such table: t_tracking_output_data_info_20210613
Traceback (most recent call last):
  File "/usr/local/lib/python3.6/site-packages/flask/app.py", line 2292, in wsgi_app
    response = self.full_dispatch_request()
  File "/usr/local/lib/python3.6/site-packages/flask/app.py", line 1815, in full_dispatch_request
    rv = self.handle_user_exception(e)
  File "/usr/local/lib/python3.6/site-packages/flask/app.py", line 1718, in handle_user_exception
    reraise(exc_type, exc_value, tb)
  File "/usr/local/lib/python3.6/site-packages/flask/_compat.py", line 35, in reraise
    raise value
  File "/usr/local/lib/python3.6/site-packages/flask/app.py", line 1813, in full_dispatch_request
    rv = self.dispatch_request()
  File "/usr/local/lib/python3.6/site-packages/flask/app.py", line 1799, in dispatch_request
    return self.view_functions[rule.endpoint](**req.view_args)
  File "/fate/python/fate_flow/apps/tracking_app.py", line 216, in component_output_data
    output_tables_meta = get_component_output_tables_meta(task_data=request_data)
  File "/fate/python/fate_flow/apps/tracking_app.py", line 377, in get_component_output_tables_meta
    output_data_table_infos = tracker.get_output_data_info()
  File "/fate/python/fate_flow/operation/job_tracker.py", line 381, in get_output_data_info
    return self.read_output_data_info_from_db(data_name=data_name)
  File "/fate/python/fate_flow/operation/job_tracker.py", line 391, in read_output_data_info_from_db
    return self.query_output_data_infos(**filter_dict)
  File "/usr/local/lib/python3.6/site-packages/peewee.py", line 394, in inner
    return fn(*args, **kwargs)
  File "/fate/python/fate_flow/operation/job_tracker.py", line 408, in query_output_data_infos
    for output_data_info in output_data_infos_tmp:
  File "/usr/local/lib/python3.6/site-packages/peewee.py", line 6246, in __iter__
    self.execute()
  File "/usr/local/lib/python3.6/site-packages/peewee.py", line 1737, in inner
    return method(self, database, *args, **kwargs)
  File "/usr/local/lib/python3.6/site-packages/peewee.py", line 1808, in execute
    return self._execute(database)
  File "/usr/local/lib/python3.6/site-packages/peewee.py", line 1982, in _execute
    cursor = database.execute(self)
  File "/usr/local/lib/python3.6/site-packages/peewee.py", line 2888, in execute
    return self.execute_sql(sql, params, commit=commit)
  File "/usr/local/lib/python3.6/site-packages/playhouse/apsw_ext.py", line 112, in execute_sql
    cursor.execute(sql, params or ())
  File "src/cursor.c", line 1019, in APSWCursor_execute.sqlite3_prepare
  File "src/statementcache.c", line 386, in sqlite3_prepare
apsw.SQLError: SQLError: no such table: t_tracking_output_data_info_20210613
[ERROR] [2021-06-13 21:11:20,383] [7:140267719124736] - api_utils.py[line:49]: [Errno 2] No such file or directory: '/fate/model_local_cache/guest#10000#guest-10000#host-10000#model/201912251046319952634/define/define_meta.yaml'
Traceback (most recent call last):
  File "/usr/local/lib/python3.6/site-packages/flask/app.py", line 2292, in wsgi_app
    response = self.full_dispatch_request()
  File "/usr/local/lib/python3.6/site-packages/flask/app.py", line 1815, in full_dispatch_request
    rv = self.handle_user_exception(e)
  File "/usr/local/lib/python3.6/site-packages/flask/app.py", line 1718, in handle_user_exception
    reraise(exc_type, exc_value, tb)
  File "/usr/local/lib/python3.6/site-packages/flask/_compat.py", line 35, in reraise
    raise value
  File "/usr/local/lib/python3.6/site-packages/flask/app.py", line 1813, in full_dispatch_request
    rv = self.dispatch_request()
  File "/usr/local/lib/python3.6/site-packages/flask/app.py", line 1799, in dispatch_request
    return self.view_functions[rule.endpoint](**req.view_args)
  File "/fate/python/fate_flow/apps/job_app.py", line 50, in submit_job
    submit_result = DAGScheduler.submit(request.json)
  File "/fate/python/fate_flow/scheduler/dag_scheduler.py", line 61, in submit
    pipeline_model = tracker.get_output_model('pipeline')
  File "/fate/python/fate_flow/operation/job_tracker.py", line 188, in get_output_model
    model_alias=model_alias)
  File "/fate/python/fate_flow/pipelined_model/pipelined_model.py", line 83, in read_component_model
    model_alias=model_alias)
  File "/fate/python/fate_flow/pipelined_model/pipelined_model.py", line 165, in get_model_proto_index
    with open(self.define_meta_path, "r", encoding="utf-8") as fr:
FileNotFoundError: [Errno 2] No such file or directory: '/fate/model_local_cache/guest#10000#guest-10000#host-10000#model/201912251046319952634/define/define_meta.yaml'
[ERROR] [2021-06-13 21:11:52,688] [7:140267719124736] - api_utils.py[line:49]: [Errno 2] No such file or directory: '/fate/model_local_cache/guest#10000#guest-10000#host-9999#model/20200928174750711017114/define/define_meta.yaml'
Traceback (most recent call last):
  File "/usr/local/lib/python3.6/site-packages/flask/app.py", line 2292, in wsgi_app
    response = self.full_dispatch_request()
  File "/usr/local/lib/python3.6/site-packages/flask/app.py", line 1815, in full_dispatch_request
    rv = self.handle_user_exception(e)
  File "/usr/local/lib/python3.6/site-packages/flask/app.py", line 1718, in handle_user_exception
    reraise(exc_type, exc_value, tb)
  File "/usr/local/lib/python3.6/site-packages/flask/_compat.py", line 35, in reraise
    raise value
  File "/usr/local/lib/python3.6/site-packages/flask/app.py", line 1813, in full_dispatch_request
    rv = self.dispatch_request()
  File "/usr/local/lib/python3.6/site-packages/flask/app.py", line 1799, in dispatch_request
    return self.view_functions[rule.endpoint](**req.view_args)
  File "/fate/python/fate_flow/apps/job_app.py", line 50, in submit_job
    submit_result = DAGScheduler.submit(request.json)
  File "/fate/python/fate_flow/scheduler/dag_scheduler.py", line 61, in submit
    pipeline_model = tracker.get_output_model('pipeline')
  File "/fate/python/fate_flow/operation/job_tracker.py", line 188, in get_output_model
    model_alias=model_alias)
  File "/fate/python/fate_flow/pipelined_model/pipelined_model.py", line 83, in read_component_model
    model_alias=model_alias)
  File "/fate/python/fate_flow/pipelined_model/pipelined_model.py", line 165, in get_model_proto_index
    with open(self.define_meta_path, "r", encoding="utf-8") as fr:
FileNotFoundError: [Errno 2] No such file or directory: '/fate/model_local_cache/guest#10000#guest-10000#host-9999#model/20200928174750711017114/define/define_meta.yaml'
[ERROR] [2021-06-13 21:15:47,166] [7:140266400880384] - api_utils.py[line:49]: [Errno 2] No such file or directory: '/fate/model_local_cache/guest#10000#guest-10000#host-9999#model/20200928174750711017114/define/define_meta.yaml'
Traceback (most recent call last):
  File "/usr/local/lib/python3.6/site-packages/flask/app.py", line 2292, in wsgi_app
    response = self.full_dispatch_request()
  File "/usr/local/lib/python3.6/site-packages/flask/app.py", line 1815, in full_dispatch_request
    rv = self.handle_user_exception(e)
  File "/usr/local/lib/python3.6/site-packages/flask/app.py", line 1718, in handle_user_exception
    reraise(exc_type, exc_value, tb)
  File "/usr/local/lib/python3.6/site-packages/flask/_compat.py", line 35, in reraise
    raise value
  File "/usr/local/lib/python3.6/site-packages/flask/app.py", line 1813, in full_dispatch_request
    rv = self.dispatch_request()
  File "/usr/local/lib/python3.6/site-packages/flask/app.py", line 1799, in dispatch_request
    return self.view_functions[rule.endpoint](**req.view_args)
  File "/fate/python/fate_flow/apps/job_app.py", line 50, in submit_job
    submit_result = DAGScheduler.submit(request.json)
  File "/fate/python/fate_flow/scheduler/dag_scheduler.py", line 61, in submit
    pipeline_model = tracker.get_output_model('pipeline')
  File "/fate/python/fate_flow/operation/job_tracker.py", line 188, in get_output_model
    model_alias=model_alias)
  File "/fate/python/fate_flow/pipelined_model/pipelined_model.py", line 83, in read_component_model
    model_alias=model_alias)
  File "/fate/python/fate_flow/pipelined_model/pipelined_model.py", line 165, in get_model_proto_index
    with open(self.define_meta_path, "r", encoding="utf-8") as fr:
FileNotFoundError: [Errno 2] No such file or directory: '/fate/model_local_cache/guest#10000#guest-10000#host-9999#model/20200928174750711017114/define/define_meta.yaml'
[ERROR] [2021-06-13 21:26:26,003] [7:140265872402176] - api_utils.py[line:49]: [Errno 2] No such file or directory: '/fate/model_local_cache/guest#10000#guest-10000#host-9999#model/20200928174750711017114/define/define_meta.yaml'
Traceback (most recent call last):
  File "/usr/local/lib/python3.6/site-packages/flask/app.py", line 2292, in wsgi_app
    response = self.full_dispatch_request()
  File "/usr/local/lib/python3.6/site-packages/flask/app.py", line 1815, in full_dispatch_request
    rv = self.handle_user_exception(e)
  File "/usr/local/lib/python3.6/site-packages/flask/app.py", line 1718, in handle_user_exception
    reraise(exc_type, exc_value, tb)
  File "/usr/local/lib/python3.6/site-packages/flask/_compat.py", line 35, in reraise
    raise value
  File "/usr/local/lib/python3.6/site-packages/flask/app.py", line 1813, in full_dispatch_request
    rv = self.dispatch_request()
  File "/usr/local/lib/python3.6/site-packages/flask/app.py", line 1799, in dispatch_request
    return self.view_functions[rule.endpoint](**req.view_args)
  File "/fate/python/fate_flow/apps/job_app.py", line 50, in submit_job
    submit_result = DAGScheduler.submit(request.json)
  File "/fate/python/fate_flow/scheduler/dag_scheduler.py", line 61, in submit
    pipeline_model = tracker.get_output_model('pipeline')
  File "/fate/python/fate_flow/operation/job_tracker.py", line 188, in get_output_model
    model_alias=model_alias)
  File "/fate/python/fate_flow/pipelined_model/pipelined_model.py", line 83, in read_component_model
    model_alias=model_alias)
  File "/fate/python/fate_flow/pipelined_model/pipelined_model.py", line 165, in get_model_proto_index
    with open(self.define_meta_path, "r", encoding="utf-8") as fr:
FileNotFoundError: [Errno 2] No such file or directory: '/fate/model_local_cache/guest#10000#guest-10000#host-9999#model/20200928174750711017114/define/define_meta.yaml'
[ERROR] [2021-06-13 21:27:13,041] [7:140265872402176] - api_utils.py[line:49]: [Errno 2] No such file or directory: '/fate/model_local_cache/guest#10000#guest-10000#host-9999#model/20200928174750711017114/define/define_meta.yaml'
Traceback (most recent call last):
  File "/usr/local/lib/python3.6/site-packages/flask/app.py", line 2292, in wsgi_app
    response = self.full_dispatch_request()
  File "/usr/local/lib/python3.6/site-packages/flask/app.py", line 1815, in full_dispatch_request
    rv = self.handle_user_exception(e)
  File "/usr/local/lib/python3.6/site-packages/flask/app.py", line 1718, in handle_user_exception
    reraise(exc_type, exc_value, tb)
  File "/usr/local/lib/python3.6/site-packages/flask/_compat.py", line 35, in reraise
    raise value
  File "/usr/local/lib/python3.6/site-packages/flask/app.py", line 1813, in full_dispatch_request
    rv = self.dispatch_request()
  File "/usr/local/lib/python3.6/site-packages/flask/app.py", line 1799, in dispatch_request
    return self.view_functions[rule.endpoint](**req.view_args)
  File "/fate/python/fate_flow/apps/job_app.py", line 50, in submit_job
    submit_result = DAGScheduler.submit(request.json)
  File "/fate/python/fate_flow/scheduler/dag_scheduler.py", line 61, in submit
    pipeline_model = tracker.get_output_model('pipeline')
  File "/fate/python/fate_flow/operation/job_tracker.py", line 188, in get_output_model
    model_alias=model_alias)
  File "/fate/python/fate_flow/pipelined_model/pipelined_model.py", line 83, in read_component_model
    model_alias=model_alias)
  File "/fate/python/fate_flow/pipelined_model/pipelined_model.py", line 165, in get_model_proto_index
    with open(self.define_meta_path, "r", encoding="utf-8") as fr:
FileNotFoundError: [Errno 2] No such file or directory: '/fate/model_local_cache/guest#10000#guest-10000#host-9999#model/20200928174750711017114/define/define_meta.yaml'
[ERROR] [2021-06-13 21:28:22,548] [7:140265872402176] - api_utils.py[line:49]: [Errno 2] No such file or directory: '/fate/model_local_cache/guest#10000#guest-10000#host-9999#model/20200928174750711017114/define/define_meta.yaml'
Traceback (most recent call last):
  File "/usr/local/lib/python3.6/site-packages/flask/app.py", line 2292, in wsgi_app
    response = self.full_dispatch_request()
  File "/usr/local/lib/python3.6/site-packages/flask/app.py", line 1815, in full_dispatch_request
    rv = self.handle_user_exception(e)
  File "/usr/local/lib/python3.6/site-packages/flask/app.py", line 1718, in handle_user_exception
    reraise(exc_type, exc_value, tb)
  File "/usr/local/lib/python3.6/site-packages/flask/_compat.py", line 35, in reraise
    raise value
  File "/usr/local/lib/python3.6/site-packages/flask/app.py", line 1813, in full_dispatch_request
    rv = self.dispatch_request()
  File "/usr/local/lib/python3.6/site-packages/flask/app.py", line 1799, in dispatch_request
    return self.view_functions[rule.endpoint](**req.view_args)
  File "/fate/python/fate_flow/apps/job_app.py", line 50, in submit_job
    submit_result = DAGScheduler.submit(request.json)
  File "/fate/python/fate_flow/scheduler/dag_scheduler.py", line 61, in submit
    pipeline_model = tracker.get_output_model('pipeline')
  File "/fate/python/fate_flow/operation/job_tracker.py", line 188, in get_output_model
    model_alias=model_alias)
  File "/fate/python/fate_flow/pipelined_model/pipelined_model.py", line 83, in read_component_model
    model_alias=model_alias)
  File "/fate/python/fate_flow/pipelined_model/pipelined_model.py", line 165, in get_model_proto_index
    with open(self.define_meta_path, "r", encoding="utf-8") as fr:
FileNotFoundError: [Errno 2] No such file or directory: '/fate/model_local_cache/guest#10000#guest-10000#host-9999#model/20200928174750711017114/define/define_meta.yaml'
[ERROR] [2021-06-13 21:34:15,492] [7:140265872402176] - api_utils.py[line:49]: [Errno 2] No such file or directory: '/fate/model_local_cache/guest#10000#guest-10000#host-9999#model/20200928174750711017114/define/define_meta.yaml'
Traceback (most recent call last):
  File "/usr/local/lib/python3.6/site-packages/flask/app.py", line 2292, in wsgi_app
    response = self.full_dispatch_request()
  File "/usr/local/lib/python3.6/site-packages/flask/app.py", line 1815, in full_dispatch_request
    rv = self.handle_user_exception(e)
  File "/usr/local/lib/python3.6/site-packages/flask/app.py", line 1718, in handle_user_exception
    reraise(exc_type, exc_value, tb)
  File "/usr/local/lib/python3.6/site-packages/flask/_compat.py", line 35, in reraise
    raise value
  File "/usr/local/lib/python3.6/site-packages/flask/app.py", line 1813, in full_dispatch_request
    rv = self.dispatch_request()
  File "/usr/local/lib/python3.6/site-packages/flask/app.py", line 1799, in dispatch_request
    return self.view_functions[rule.endpoint](**req.view_args)
  File "/fate/python/fate_flow/apps/job_app.py", line 50, in submit_job
    submit_result = DAGScheduler.submit(request.json)
  File "/fate/python/fate_flow/scheduler/dag_scheduler.py", line 61, in submit
    pipeline_model = tracker.get_output_model('pipeline')
  File "/fate/python/fate_flow/operation/job_tracker.py", line 188, in get_output_model
    model_alias=model_alias)
  File "/fate/python/fate_flow/pipelined_model/pipelined_model.py", line 83, in read_component_model
    model_alias=model_alias)
  File "/fate/python/fate_flow/pipelined_model/pipelined_model.py", line 165, in get_model_proto_index
    with open(self.define_meta_path, "r", encoding="utf-8") as fr:
FileNotFoundError: [Errno 2] No such file or directory: '/fate/model_local_cache/guest#10000#guest-10000#host-9999#model/20200928174750711017114/define/define_meta.yaml'
[ERROR] [2021-06-13 21:38:38,645] [7:140265872402176] - api_utils.py[line:49]: [Errno 2] No such file or directory: '/fate/model_local_cache/guest#10000#guest-9999#host-9998#model/2021061321344671179618/define/define_meta.yaml'
Traceback (most recent call last):
  File "/usr/local/lib/python3.6/site-packages/flask/app.py", line 2292, in wsgi_app
    response = self.full_dispatch_request()
  File "/usr/local/lib/python3.6/site-packages/flask/app.py", line 1815, in full_dispatch_request
    rv = self.handle_user_exception(e)
  File "/usr/local/lib/python3.6/site-packages/flask/app.py", line 1718, in handle_user_exception
    reraise(exc_type, exc_value, tb)
  File "/usr/local/lib/python3.6/site-packages/flask/_compat.py", line 35, in reraise
    raise value
  File "/usr/local/lib/python3.6/site-packages/flask/app.py", line 1813, in full_dispatch_request
    rv = self.dispatch_request()
  File "/usr/local/lib/python3.6/site-packages/flask/app.py", line 1799, in dispatch_request
    return self.view_functions[rule.endpoint](**req.view_args)
  File "/fate/python/fate_flow/apps/job_app.py", line 50, in submit_job
    submit_result = DAGScheduler.submit(request.json)
  File "/fate/python/fate_flow/scheduler/dag_scheduler.py", line 61, in submit
    pipeline_model = tracker.get_output_model('pipeline')
  File "/fate/python/fate_flow/operation/job_tracker.py", line 188, in get_output_model
    model_alias=model_alias)
  File "/fate/python/fate_flow/pipelined_model/pipelined_model.py", line 83, in read_component_model
    model_alias=model_alias)
  File "/fate/python/fate_flow/pipelined_model/pipelined_model.py", line 165, in get_model_proto_index
    with open(self.define_meta_path, "r", encoding="utf-8") as fr:
FileNotFoundError: [Errno 2] No such file or directory: '/fate/model_local_cache/guest#10000#guest-9999#host-9998#model/2021061321344671179618/define/define_meta.yaml'
[ERROR] [2021-06-13 21:41:54,012] [7:140265872402176] - deploy_model.py[line:114]: Child model could not be deployed.
Traceback (most recent call last):
  File "/fate/python/fate_flow/pipelined_model/deploy_model.py", line 44, in deploy
    raise Exception('Child model could not be deployed.')
Exception: Child model could not be deployed.
[ERROR] [2021-06-13 21:41:54,081] [7:140265872402176] - deploy_model.py[line:114]: Child model could not be deployed.
Traceback (most recent call last):
  File "/fate/python/fate_flow/pipelined_model/deploy_model.py", line 44, in deploy
    raise Exception('Child model could not be deployed.')
Exception: Child model could not be deployed.
[ERROR] [2021-06-13 21:44:33,216] [7:140266400880384] - api_utils.py[line:49]: [Errno 2] No such file or directory: '/fate/model_local_cache/guest#10000#guest-9999#host-9998#model/202106132103219414043/define/define_meta.yaml'
Traceback (most recent call last):
  File "/usr/local/lib/python3.6/site-packages/flask/app.py", line 2292, in wsgi_app
    response = self.full_dispatch_request()
  File "/usr/local/lib/python3.6/site-packages/flask/app.py", line 1815, in full_dispatch_request
    rv = self.handle_user_exception(e)
  File "/usr/local/lib/python3.6/site-packages/flask/app.py", line 1718, in handle_user_exception
    reraise(exc_type, exc_value, tb)
  File "/usr/local/lib/python3.6/site-packages/flask/_compat.py", line 35, in reraise
    raise value
  File "/usr/local/lib/python3.6/site-packages/flask/app.py", line 1813, in full_dispatch_request
    rv = self.dispatch_request()
  File "/usr/local/lib/python3.6/site-packages/flask/app.py", line 1799, in dispatch_request
    return self.view_functions[rule.endpoint](**req.view_args)
  File "/fate/python/fate_flow/apps/job_app.py", line 50, in submit_job
    submit_result = DAGScheduler.submit(request.json)
  File "/fate/python/fate_flow/scheduler/dag_scheduler.py", line 61, in submit
    pipeline_model = tracker.get_output_model('pipeline')
  File "/fate/python/fate_flow/operation/job_tracker.py", line 188, in get_output_model
    model_alias=model_alias)
  File "/fate/python/fate_flow/pipelined_model/pipelined_model.py", line 83, in read_component_model
    model_alias=model_alias)
  File "/fate/python/fate_flow/pipelined_model/pipelined_model.py", line 165, in get_model_proto_index
    with open(self.define_meta_path, "r", encoding="utf-8") as fr:
FileNotFoundError: [Errno 2] No such file or directory: '/fate/model_local_cache/guest#10000#guest-9999#host-9998#model/202106132103219414043/define/define_meta.yaml'
[ERROR] [2021-06-13 21:53:07,325] [7:140266400880384] - api_utils.py[line:49]: [Errno 2] No such file or directory: '/fate/model_local_cache/guest#10000#guest-9999#host-9998#model/202106132103219414043/define/define_meta.yaml'
Traceback (most recent call last):
  File "/usr/local/lib/python3.6/site-packages/flask/app.py", line 2292, in wsgi_app
    response = self.full_dispatch_request()
  File "/usr/local/lib/python3.6/site-packages/flask/app.py", line 1815, in full_dispatch_request
    rv = self.handle_user_exception(e)
  File "/usr/local/lib/python3.6/site-packages/flask/app.py", line 1718, in handle_user_exception
    reraise(exc_type, exc_value, tb)
  File "/usr/local/lib/python3.6/site-packages/flask/_compat.py", line 35, in reraise
    raise value
  File "/usr/local/lib/python3.6/site-packages/flask/app.py", line 1813, in full_dispatch_request
    rv = self.dispatch_request()
  File "/usr/local/lib/python3.6/site-packages/flask/app.py", line 1799, in dispatch_request
    return self.view_functions[rule.endpoint](**req.view_args)
  File "/fate/python/fate_flow/apps/job_app.py", line 50, in submit_job
    submit_result = DAGScheduler.submit(request.json)
  File "/fate/python/fate_flow/scheduler/dag_scheduler.py", line 61, in submit
    pipeline_model = tracker.get_output_model('pipeline')
  File "/fate/python/fate_flow/operation/job_tracker.py", line 188, in get_output_model
    model_alias=model_alias)
  File "/fate/python/fate_flow/pipelined_model/pipelined_model.py", line 83, in read_component_model
    model_alias=model_alias)
  File "/fate/python/fate_flow/pipelined_model/pipelined_model.py", line 165, in get_model_proto_index
    with open(self.define_meta_path, "r", encoding="utf-8") as fr:
FileNotFoundError: [Errno 2] No such file or directory: '/fate/model_local_cache/guest#10000#guest-9999#host-9998#model/202106132103219414043/define/define_meta.yaml'
[ERROR] [2021-06-13 21:55:33,855] [7:140266400880384] - api_utils.py[line:49]: [Errno 2] No such file or directory: '/fate/model_local_cache/guest#10000#guest-9999#host-9998#model/202106132103219414043/define/define_meta.yaml'
Traceback (most recent call last):
  File "/usr/local/lib/python3.6/site-packages/flask/app.py", line 2292, in wsgi_app
    response = self.full_dispatch_request()
  File "/usr/local/lib/python3.6/site-packages/flask/app.py", line 1815, in full_dispatch_request
    rv = self.handle_user_exception(e)
  File "/usr/local/lib/python3.6/site-packages/flask/app.py", line 1718, in handle_user_exception
    reraise(exc_type, exc_value, tb)
  File "/usr/local/lib/python3.6/site-packages/flask/_compat.py", line 35, in reraise
    raise value
  File "/usr/local/lib/python3.6/site-packages/flask/app.py", line 1813, in full_dispatch_request
    rv = self.dispatch_request()
  File "/usr/local/lib/python3.6/site-packages/flask/app.py", line 1799, in dispatch_request
    return self.view_functions[rule.endpoint](**req.view_args)
  File "/fate/python/fate_flow/apps/job_app.py", line 50, in submit_job
    submit_result = DAGScheduler.submit(request.json)
  File "/fate/python/fate_flow/scheduler/dag_scheduler.py", line 61, in submit
    pipeline_model = tracker.get_output_model('pipeline')
  File "/fate/python/fate_flow/operation/job_tracker.py", line 188, in get_output_model
    model_alias=model_alias)
  File "/fate/python/fate_flow/pipelined_model/pipelined_model.py", line 83, in read_component_model
    model_alias=model_alias)
  File "/fate/python/fate_flow/pipelined_model/pipelined_model.py", line 165, in get_model_proto_index
    with open(self.define_meta_path, "r", encoding="utf-8") as fr:
FileNotFoundError: [Errno 2] No such file or directory: '/fate/model_local_cache/guest#10000#guest-9999#host-9998#model/202106132103219414043/define/define_meta.yaml'
[ERROR] [2021-06-13 22:04:40,357] [7:140265872402176] - api_utils.py[line:49]: [Errno 2] No such file or directory: '/fate/model_local_cache/guest#10000#guest-9999#host-9998#model/202106132103219414043/define/define_meta.yaml'
Traceback (most recent call last):
  File "/usr/local/lib/python3.6/site-packages/flask/app.py", line 2292, in wsgi_app
    response = self.full_dispatch_request()
  File "/usr/local/lib/python3.6/site-packages/flask/app.py", line 1815, in full_dispatch_request
    rv = self.handle_user_exception(e)
  File "/usr/local/lib/python3.6/site-packages/flask/app.py", line 1718, in handle_user_exception
    reraise(exc_type, exc_value, tb)
  File "/usr/local/lib/python3.6/site-packages/flask/_compat.py", line 35, in reraise
    raise value
  File "/usr/local/lib/python3.6/site-packages/flask/app.py", line 1813, in full_dispatch_request
    rv = self.dispatch_request()
  File "/usr/local/lib/python3.6/site-packages/flask/app.py", line 1799, in dispatch_request
    return self.view_functions[rule.endpoint](**req.view_args)
  File "/fate/python/fate_flow/apps/job_app.py", line 50, in submit_job
    submit_result = DAGScheduler.submit(request.json)
  File "/fate/python/fate_flow/scheduler/dag_scheduler.py", line 61, in submit
    pipeline_model = tracker.get_output_model('pipeline')
  File "/fate/python/fate_flow/operation/job_tracker.py", line 188, in get_output_model
    model_alias=model_alias)
  File "/fate/python/fate_flow/pipelined_model/pipelined_model.py", line 83, in read_component_model
    model_alias=model_alias)
  File "/fate/python/fate_flow/pipelined_model/pipelined_model.py", line 165, in get_model_proto_index
    with open(self.define_meta_path, "r", encoding="utf-8") as fr:
FileNotFoundError: [Errno 2] No such file or directory: '/fate/model_local_cache/guest#10000#guest-9999#host-9998#model/202106132103219414043/define/define_meta.yaml'
[ERROR] [2021-06-13 22:08:06,855] [7:140266442843904] - api_utils.py[line:49]: [Errno 2] No such file or directory: '/fate/model_local_cache/guest#9998#guest-9999#host-9998#model/202106132103219414043/define/define_meta.yaml'
Traceback (most recent call last):
  File "/usr/local/lib/python3.6/site-packages/flask/app.py", line 2292, in wsgi_app
    response = self.full_dispatch_request()
  File "/usr/local/lib/python3.6/site-packages/flask/app.py", line 1815, in full_dispatch_request
    rv = self.handle_user_exception(e)
  File "/usr/local/lib/python3.6/site-packages/flask/app.py", line 1718, in handle_user_exception
    reraise(exc_type, exc_value, tb)
  File "/usr/local/lib/python3.6/site-packages/flask/_compat.py", line 35, in reraise
    raise value
  File "/usr/local/lib/python3.6/site-packages/flask/app.py", line 1813, in full_dispatch_request
    rv = self.dispatch_request()
  File "/usr/local/lib/python3.6/site-packages/flask/app.py", line 1799, in dispatch_request
    return self.view_functions[rule.endpoint](**req.view_args)
  File "/fate/python/fate_flow/apps/job_app.py", line 50, in submit_job
    submit_result = DAGScheduler.submit(request.json)
  File "/fate/python/fate_flow/scheduler/dag_scheduler.py", line 61, in submit
    pipeline_model = tracker.get_output_model('pipeline')
  File "/fate/python/fate_flow/operation/job_tracker.py", line 188, in get_output_model
    model_alias=model_alias)
  File "/fate/python/fate_flow/pipelined_model/pipelined_model.py", line 83, in read_component_model
    model_alias=model_alias)
  File "/fate/python/fate_flow/pipelined_model/pipelined_model.py", line 165, in get_model_proto_index
    with open(self.define_meta_path, "r", encoding="utf-8") as fr:
FileNotFoundError: [Errno 2] No such file or directory: '/fate/model_local_cache/guest#9998#guest-9999#host-9998#model/202106132103219414043/define/define_meta.yaml'
[ERROR] [2021-06-13 22:10:30,914] [7:140266442843904] - api_utils.py[line:49]: [Errno 2] No such file or directory: '/fate/model_local_cache/guest#10000#guest-10000#host-10000#model/201912251046319952634/define/define_meta.yaml'
Traceback (most recent call last):
  File "/usr/local/lib/python3.6/site-packages/flask/app.py", line 2292, in wsgi_app
    response = self.full_dispatch_request()
  File "/usr/local/lib/python3.6/site-packages/flask/app.py", line 1815, in full_dispatch_request
    rv = self.handle_user_exception(e)
  File "/usr/local/lib/python3.6/site-packages/flask/app.py", line 1718, in handle_user_exception
    reraise(exc_type, exc_value, tb)
  File "/usr/local/lib/python3.6/site-packages/flask/_compat.py", line 35, in reraise
    raise value
  File "/usr/local/lib/python3.6/site-packages/flask/app.py", line 1813, in full_dispatch_request
    rv = self.dispatch_request()
  File "/usr/local/lib/python3.6/site-packages/flask/app.py", line 1799, in dispatch_request
    return self.view_functions[rule.endpoint](**req.view_args)
  File "/fate/python/fate_flow/apps/job_app.py", line 50, in submit_job
    submit_result = DAGScheduler.submit(request.json)
  File "/fate/python/fate_flow/scheduler/dag_scheduler.py", line 61, in submit
    pipeline_model = tracker.get_output_model('pipeline')
  File "/fate/python/fate_flow/operation/job_tracker.py", line 188, in get_output_model
    model_alias=model_alias)
  File "/fate/python/fate_flow/pipelined_model/pipelined_model.py", line 83, in read_component_model
    model_alias=model_alias)
  File "/fate/python/fate_flow/pipelined_model/pipelined_model.py", line 165, in get_model_proto_index
    with open(self.define_meta_path, "r", encoding="utf-8") as fr:
FileNotFoundError: [Errno 2] No such file or directory: '/fate/model_local_cache/guest#10000#guest-10000#host-10000#model/201912251046319952634/define/define_meta.yaml'
[ERROR] [2021-06-13 22:17:45,878] [7:140265377494784] - api_utils.py[line:49]: [Errno 2] No such file or directory: '/fate/model_local_cache/guest#10000#guest-9999#host-9998#model/202106132103219414043/define/define_meta.yaml'
Traceback (most recent call last):
  File "/usr/local/lib/python3.6/site-packages/flask/app.py", line 2292, in wsgi_app
    response = self.full_dispatch_request()
  File "/usr/local/lib/python3.6/site-packages/flask/app.py", line 1815, in full_dispatch_request
    rv = self.handle_user_exception(e)
  File "/usr/local/lib/python3.6/site-packages/flask/app.py", line 1718, in handle_user_exception
    reraise(exc_type, exc_value, tb)
  File "/usr/local/lib/python3.6/site-packages/flask/_compat.py", line 35, in reraise
    raise value
  File "/usr/local/lib/python3.6/site-packages/flask/app.py", line 1813, in full_dispatch_request
    rv = self.dispatch_request()
  File "/usr/local/lib/python3.6/site-packages/flask/app.py", line 1799, in dispatch_request
    return self.view_functions[rule.endpoint](**req.view_args)
  File "/fate/python/fate_flow/apps/job_app.py", line 50, in submit_job
    submit_result = DAGScheduler.submit(request.json)
  File "/fate/python/fate_flow/scheduler/dag_scheduler.py", line 61, in submit
    pipeline_model = tracker.get_output_model('pipeline')
  File "/fate/python/fate_flow/operation/job_tracker.py", line 188, in get_output_model
    model_alias=model_alias)
  File "/fate/python/fate_flow/pipelined_model/pipelined_model.py", line 83, in read_component_model
    model_alias=model_alias)
  File "/fate/python/fate_flow/pipelined_model/pipelined_model.py", line 165, in get_model_proto_index
    with open(self.define_meta_path, "r", encoding="utf-8") as fr:
FileNotFoundError: [Errno 2] No such file or directory: '/fate/model_local_cache/guest#10000#guest-9999#host-9998#model/202106132103219414043/define/define_meta.yaml'
[ERROR] [2021-06-13 22:25:07,809] [7:140265377494784] - api_utils.py[line:49]: Model guest-9999#host-9998#model 202106132103219414043 has not been deployed yet.
Traceback (most recent call last):
  File "/usr/local/lib/python3.6/site-packages/flask/app.py", line 2292, in wsgi_app
    response = self.full_dispatch_request()
  File "/usr/local/lib/python3.6/site-packages/flask/app.py", line 1815, in full_dispatch_request
    rv = self.handle_user_exception(e)
  File "/usr/local/lib/python3.6/site-packages/flask/app.py", line 1718, in handle_user_exception
    reraise(exc_type, exc_value, tb)
  File "/usr/local/lib/python3.6/site-packages/flask/_compat.py", line 35, in reraise
    raise value
  File "/usr/local/lib/python3.6/site-packages/flask/app.py", line 1813, in full_dispatch_request
    rv = self.dispatch_request()
  File "/usr/local/lib/python3.6/site-packages/flask/app.py", line 1799, in dispatch_request
    return self.view_functions[rule.endpoint](**req.view_args)
  File "/fate/python/fate_flow/apps/job_app.py", line 50, in submit_job
    submit_result = DAGScheduler.submit(request.json)
  File "/fate/python/fate_flow/scheduler/dag_scheduler.py", line 67, in submit
    raise Exception(f"Model {common_job_parameters.model_id} {common_job_parameters.model_version} has not been deployed yet.")
Exception: Model guest-9999#host-9998#model 202106132103219414043 has not been deployed yet.
[ERROR] [2021-06-13 22:25:30,421] [7:140265377494784] - api_utils.py[line:49]: Model guest-9999#host-9998#model 202106132103219414043 has not been deployed yet.
Traceback (most recent call last):
  File "/usr/local/lib/python3.6/site-packages/flask/app.py", line 2292, in wsgi_app
    response = self.full_dispatch_request()
  File "/usr/local/lib/python3.6/site-packages/flask/app.py", line 1815, in full_dispatch_request
    rv = self.handle_user_exception(e)
  File "/usr/local/lib/python3.6/site-packages/flask/app.py", line 1718, in handle_user_exception
    reraise(exc_type, exc_value, tb)
  File "/usr/local/lib/python3.6/site-packages/flask/_compat.py", line 35, in reraise
    raise value
  File "/usr/local/lib/python3.6/site-packages/flask/app.py", line 1813, in full_dispatch_request
    rv = self.dispatch_request()
  File "/usr/local/lib/python3.6/site-packages/flask/app.py", line 1799, in dispatch_request
    return self.view_functions[rule.endpoint](**req.view_args)
  File "/fate/python/fate_flow/apps/job_app.py", line 50, in submit_job
    submit_result = DAGScheduler.submit(request.json)
  File "/fate/python/fate_flow/scheduler/dag_scheduler.py", line 67, in submit
    raise Exception(f"Model {common_job_parameters.model_id} {common_job_parameters.model_version} has not been deployed yet.")
Exception: Model guest-9999#host-9998#model 202106132103219414043 has not been deployed yet.
[ERROR] [2021-06-13 22:26:09,989] [7:140265377494784] - api_utils.py[line:49]: Model guest-9999#host-9998#model 202106132103219414043 has not been deployed yet.
Traceback (most recent call last):
  File "/usr/local/lib/python3.6/site-packages/flask/app.py", line 2292, in wsgi_app
    response = self.full_dispatch_request()
  File "/usr/local/lib/python3.6/site-packages/flask/app.py", line 1815, in full_dispatch_request
    rv = self.handle_user_exception(e)
  File "/usr/local/lib/python3.6/site-packages/flask/app.py", line 1718, in handle_user_exception
    reraise(exc_type, exc_value, tb)
  File "/usr/local/lib/python3.6/site-packages/flask/_compat.py", line 35, in reraise
    raise value
  File "/usr/local/lib/python3.6/site-packages/flask/app.py", line 1813, in full_dispatch_request
    rv = self.dispatch_request()
  File "/usr/local/lib/python3.6/site-packages/flask/app.py", line 1799, in dispatch_request
    return self.view_functions[rule.endpoint](**req.view_args)
  File "/fate/python/fate_flow/apps/job_app.py", line 50, in submit_job
    submit_result = DAGScheduler.submit(request.json)
  File "/fate/python/fate_flow/scheduler/dag_scheduler.py", line 67, in submit
    raise Exception(f"Model {common_job_parameters.model_id} {common_job_parameters.model_version} has not been deployed yet.")
Exception: Model guest-9999#host-9998#model 202106132103219414043 has not been deployed yet.
[ERROR] [2021-06-13 22:27:02,200] [7:140265377494784] - api_utils.py[line:49]: Model guest-9999#host-9998#model 202106132103219414043 has not been deployed yet.
Traceback (most recent call last):
  File "/usr/local/lib/python3.6/site-packages/flask/app.py", line 2292, in wsgi_app
    response = self.full_dispatch_request()
  File "/usr/local/lib/python3.6/site-packages/flask/app.py", line 1815, in full_dispatch_request
    rv = self.handle_user_exception(e)
  File "/usr/local/lib/python3.6/site-packages/flask/app.py", line 1718, in handle_user_exception
    reraise(exc_type, exc_value, tb)
  File "/usr/local/lib/python3.6/site-packages/flask/_compat.py", line 35, in reraise
    raise value
  File "/usr/local/lib/python3.6/site-packages/flask/app.py", line 1813, in full_dispatch_request
    rv = self.dispatch_request()
  File "/usr/local/lib/python3.6/site-packages/flask/app.py", line 1799, in dispatch_request
    return self.view_functions[rule.endpoint](**req.view_args)
  File "/fate/python/fate_flow/apps/job_app.py", line 50, in submit_job
    submit_result = DAGScheduler.submit(request.json)
  File "/fate/python/fate_flow/scheduler/dag_scheduler.py", line 67, in submit
    raise Exception(f"Model {common_job_parameters.model_id} {common_job_parameters.model_version} has not been deployed yet.")
Exception: Model guest-9999#host-9998#model 202106132103219414043 has not been deployed yet.
[ERROR] [2021-06-13 22:31:04,161] [7:140266409273088] - initiator_app.py[line:32]: Create <Model: Task> failed:
ConstraintError: UNIQUE constraint failed: t_task.f_job_id, t_task.f_task_id, t_task.f_task_version, t_task.f_role, t_task.f_party_id
Traceback (most recent call last):
  File "/usr/local/lib/python3.6/site-packages/playhouse/apsw_ext.py", line 112, in execute_sql
    cursor.execute(sql, params or ())
  File "src/cursor.c", line 236, in resetcursor
apsw.ConstraintError: ConstraintError: UNIQUE constraint failed: t_task.f_job_id, t_task.f_task_id, t_task.f_task_version, t_task.f_role, t_task.f_party_id

During handling of the above exception, another exception occurred:

Traceback (most recent call last):
  File "/fate/python/fate_flow/operation/job_saver.py", line 99, in create_job_family_entity
    rows = obj.save(force_insert=True)
  File "/fate/python/fate_arch/storage/metastore/base_model.py", line 89, in save
    return super(BaseModel, self).save(*args, **kwargs)
  File "/usr/local/lib/python3.6/site-packages/peewee.py", line 5964, in save
    self.insert(**field_dict).execute()
  File "/usr/local/lib/python3.6/site-packages/peewee.py", line 1737, in inner
    return method(self, database, *args, **kwargs)
  File "/usr/local/lib/python3.6/site-packages/peewee.py", line 1808, in execute
    return self._execute(database)
  File "/usr/local/lib/python3.6/site-packages/peewee.py", line 2512, in _execute
    return super(Insert, self)._execute(database)
  File "/usr/local/lib/python3.6/site-packages/peewee.py", line 2275, in _execute
    cursor = database.execute(self)
  File "/usr/local/lib/python3.6/site-packages/peewee.py", line 2888, in execute
    return self.execute_sql(sql, params, commit=commit)
  File "/usr/local/lib/python3.6/site-packages/playhouse/apsw_ext.py", line 112, in execute_sql
    cursor.execute(sql, params or ())
  File "/usr/local/lib/python3.6/site-packages/peewee.py", line 2666, in __exit__
    reraise(new_type, new_type(*exc_args), traceback)
  File "/usr/local/lib/python3.6/site-packages/peewee.py", line 179, in reraise
    raise value.with_traceback(tb)
  File "/usr/local/lib/python3.6/site-packages/playhouse/apsw_ext.py", line 112, in execute_sql
    cursor.execute(sql, params or ())
  File "src/cursor.c", line 236, in resetcursor
peewee.IntegrityError: ConstraintError: UNIQUE constraint failed: t_task.f_job_id, t_task.f_task_id, t_task.f_task_version, t_task.f_role, t_task.f_party_id

During handling of the above exception, another exception occurred:

Traceback (most recent call last):
  File "/usr/local/lib/python3.6/site-packages/flask/app.py", line 2292, in wsgi_app
    response = self.full_dispatch_request()
  File "/usr/local/lib/python3.6/site-packages/flask/app.py", line 1815, in full_dispatch_request
    rv = self.handle_user_exception(e)
  File "/usr/local/lib/python3.6/site-packages/flask/app.py", line 1718, in handle_user_exception
    reraise(exc_type, exc_value, tb)
  File "/usr/local/lib/python3.6/site-packages/flask/_compat.py", line 35, in reraise
    raise value
  File "/usr/local/lib/python3.6/site-packages/flask/app.py", line 1813, in full_dispatch_request
    rv = self.dispatch_request()
  File "/usr/local/lib/python3.6/site-packages/flask/app.py", line 1799, in dispatch_request
    return self.view_functions[rule.endpoint](**req.view_args)
  File "/fate/python/fate_flow/scheduling_apps/initiator_app.py", line 48, in rerun_job
    component_name=request.json.get("component_name"))
  File "/fate/python/fate_flow/scheduler/dag_scheduler.py", line 363, in rerun_job
    JobController.initialize_tasks(job_id, _role, _party_id, False, job.f_initiator_role, job.f_initiator_party_id, RunParameters(**job.f_runtime_conf_on_party["job_parameters"]), dsl_parser, component_name=task.f_component_name, task_version=task.f_task_version)
  File "/fate/python/fate_flow/controller/job_controller.py", line 192, in initialize_tasks
    role=role, party_id=party_id, run_on_this_party=run_on_this_party, task_info=task_info)
  File "/fate/python/fate_flow/controller/task_controller.py", line 52, in create_task
    JobSaver.create_task(task_info=task_info)
  File "/fate/python/fate_flow/operation/job_saver.py", line 36, in create_task
    return cls.create_job_family_entity(Task, task_info)
  File "/usr/local/lib/python3.6/site-packages/peewee.py", line 394, in inner
    return fn(*args, **kwargs)
  File "/fate/python/fate_flow/operation/job_saver.py", line 107, in create_job_family_entity
    raise Exception("Create {} failed:\n{}".format(entity_model, e))
Exception: Create <Model: Task> failed:
ConstraintError: UNIQUE constraint failed: t_task.f_job_id, t_task.f_task_id, t_task.f_task_version, t_task.f_role, t_task.f_party_id
