[ERROR] [2021-06-15 21:01:16,661] [7:140195651385088] - job_tracker.py[line:475]: namespace dir /fate/data/202106152101093465361_reader_1_0_host_9998 does not exist
Traceback (most recent call last):
  File "/fate/python/fate_flow/operation/job_tracker.py", line 437, in clean_task
    sess.computing.cleanup(namespace=computing_temp_namespace, name="*")
  File "/fate/python/fate_arch/computing/standalone/_csession.py", line 73, in cleanup
    return self._session.cleanup(name=name, namespace=namespace)
  File "/fate/python/fate_arch/_standalone.py", line 383, in cleanup
    raise EnvironmentError(f"namespace dir {namespace_dir} does not exist")
OSError: namespace dir /fate/data/202106152101093465361_reader_1_0_host_9998 does not exist
[ERROR] [2021-06-15 21:01:16,725] [7:140195651385088] - job_tracker.py[line:475]: namespace dir /fate/data/202106152101093465361_reader_1_0_guest_9999 does not exist
Traceback (most recent call last):
  File "/fate/python/fate_flow/operation/job_tracker.py", line 437, in clean_task
    sess.computing.cleanup(namespace=computing_temp_namespace, name="*")
  File "/fate/python/fate_arch/computing/standalone/_csession.py", line 73, in cleanup
    return self._session.cleanup(name=name, namespace=namespace)
  File "/fate/python/fate_arch/_standalone.py", line 383, in cleanup
    raise EnvironmentError(f"namespace dir {namespace_dir} does not exist")
OSError: namespace dir /fate/data/202106152101093465361_reader_1_0_guest_9999 does not exist
[ERROR] [2021-06-15 21:01:22,146] [7:140195651385088] - job_tracker.py[line:475]: namespace dir /fate/data/202106152101093465361_reader_0_0_host_9998 does not exist
Traceback (most recent call last):
  File "/fate/python/fate_flow/operation/job_tracker.py", line 437, in clean_task
    sess.computing.cleanup(namespace=computing_temp_namespace, name="*")
  File "/fate/python/fate_arch/computing/standalone/_csession.py", line 73, in cleanup
    return self._session.cleanup(name=name, namespace=namespace)
  File "/fate/python/fate_arch/_standalone.py", line 383, in cleanup
    raise EnvironmentError(f"namespace dir {namespace_dir} does not exist")
OSError: namespace dir /fate/data/202106152101093465361_reader_0_0_host_9998 does not exist
[ERROR] [2021-06-15 21:01:22,204] [7:140195651385088] - job_tracker.py[line:475]: namespace dir /fate/data/202106152101093465361_reader_0_0_guest_9999 does not exist
Traceback (most recent call last):
  File "/fate/python/fate_flow/operation/job_tracker.py", line 437, in clean_task
    sess.computing.cleanup(namespace=computing_temp_namespace, name="*")
  File "/fate/python/fate_arch/computing/standalone/_csession.py", line 73, in cleanup
    return self._session.cleanup(name=name, namespace=namespace)
  File "/fate/python/fate_arch/_standalone.py", line 383, in cleanup
    raise EnvironmentError(f"namespace dir {namespace_dir} does not exist")
OSError: namespace dir /fate/data/202106152101093465361_reader_0_0_guest_9999 does not exist
[ERROR] [2021-06-15 21:02:54,642] [7:140196683163392] - job_tracker.py[line:475]: namespace dir /fate/data/202106152101093465361_evaluation_0_0_host_9998 does not exist
Traceback (most recent call last):
  File "/fate/python/fate_flow/operation/job_tracker.py", line 437, in clean_task
    sess.computing.cleanup(namespace=computing_temp_namespace, name="*")
  File "/fate/python/fate_arch/computing/standalone/_csession.py", line 73, in cleanup
    return self._session.cleanup(name=name, namespace=namespace)
  File "/fate/python/fate_arch/_standalone.py", line 383, in cleanup
    raise EnvironmentError(f"namespace dir {namespace_dir} does not exist")
OSError: namespace dir /fate/data/202106152101093465361_evaluation_0_0_host_9998 does not exist
[ERROR] [2021-06-15 21:02:54,691] [7:140196683163392] - job_tracker.py[line:475]: namespace dir /fate/data/202106152101093465361_evaluation_0_0_guest_9999 does not exist
Traceback (most recent call last):
  File "/fate/python/fate_flow/operation/job_tracker.py", line 437, in clean_task
    sess.computing.cleanup(namespace=computing_temp_namespace, name="*")
  File "/fate/python/fate_arch/computing/standalone/_csession.py", line 73, in cleanup
    return self._session.cleanup(name=name, namespace=namespace)
  File "/fate/python/fate_arch/_standalone.py", line 383, in cleanup
    raise EnvironmentError(f"namespace dir {namespace_dir} does not exist")
OSError: namespace dir /fate/data/202106152101093465361_evaluation_0_0_guest_9999 does not exist
